Workbook

Sheet นับเกื้อกูล
A1: แปลง พศ เป็น คศ => | B1: 243497 | C1: =IF(AND(LEFT(B1,2)="29",MID(B1,4,1)="2"),LEFT(B1,2)&"/"&MID(B1,4,1)&"/"&RIGHT(B1,4)-543,EDATE(B1,-543*12)) -> 45170
A2: เลข ปชช | B2: เกื้อกูล เริ่มต้น | C2: เกื้อกูล สิ้นสุด | D2: ปี | E2: เดือน | F2: วัน | G2: จำนวนวันทั้งหมด | H2: สัดส่วน (%) | I2: จำนวนวันเกื้อกูล | J2: เกื้อกูล สิ้นสุด สุทธิ | K2: ปี เกื้อกูลสุทธิ | L2: เดือน เกื้อกูลสุทธิ | M2: วัน เกื้อกูลสุทธิ
A3: 1234567890001 | B3: 42005 | C3: 43101 | D3: =DATEDIF(B3,C3,"Y") -> 3 | E3: =DATEDIF(B3,C3,"YM") -> 0 | F3: =DATEDIF(B3,C3,"MD") -> 0 | G3: =C3-B3 -> 1096 | H3: 100 | I3: =G3*H3% -> 1096 | J3: =B3+I3 -> 43101 | K3: =DATEDIF(B3,J3,"Y") -> 3 | L3: =DATEDIF(B3,J3,"YM") -> 0 | M3: =DATEDIF(B3,J3,"MD") -> 0
A4: 1234567890002 | B4: 42005 | C4: 43101 | D4: =DATEDIF(B4,C4,"Y") -> 3 | E4: =DATEDIF(B4,C4,"YM") -> 0 | F4: =DATEDIF(B4,C4,"MD") -> 0 | G4: =C4-B4 -> 1096 | H4: 50 | I4: =G4*H4% -> 548 | J4: =B4+I4 -> 42553 | K4: =DATEDIF(B4,J4,"Y") -> 1 | L4: =DATEDIF(B4,J4,"YM") -> 6 | M4: =DATEDIF(B4,J4,"MD") -> 1
A5: 1234567890003 | B5: 40725 | C5: 45214 | D5: =DATEDIF(B5,C5,"Y") -> 12 | E5: =DATEDIF(B5,C5,"YM") -> 3 | F5: =DATEDIF(B5,C5,"MD") -> 14 | G5: =C5-B5 -> 4489 | H5: 100 | I5: =G5*H5% -> 4489 | J5: =B5+I5 -> 45214 | K5: =DATEDIF(B5,J5,"Y") -> 12 | L5: =DATEDIF(B5,J5,"YM") -> 3 | M5: =DATEDIF(B5,J5,"MD") -> 14
A6: 1234567890004 | B6: 43800 | C6: 45170 | D6: =DATEDIF(B6,C6,"Y") -> 3 | E6: =DATEDIF(B6,C6,"YM") -> 9 | F6: =DATEDIF(B6,C6,"MD") -> 0 | G6: =C6-B6 -> 1370 | H6: 100 | I6: =G6*H6% -> 1370 | J6: =B6+I6 -> 45170 | K6: =DATEDIF(B6,J6,"Y") -> 3 | L6: =DATEDIF(B6,J6,"YM") -> 9 | M6: =DATEDIF(B6,J6,"MD") -> 0
A7: 1234567890005 | B7: 38353 | C7: 40909 | D7: =DATEDIF(B7,C7,"Y") -> 7 | E7: =DATEDIF(B7,C7,"YM") -> 0 | F7: =DATEDIF(B7,C7,"MD") -> 0 | G7: =C7-B7 -> 2556 | H7: 80 | I7: =G7*H7% -> 2044.8 | J7: =B7+I7 -> 40397.8 | K7: =DATEDIF(B7,J7,"Y") -> 5 | L7: =DATEDIF(B7,J7,"YM") -> 7 | M7: =DATEDIF(B7,J7,"MD") -> 6
A8: 1234567890006 | B8: 44927 | C8: =TODAY() -> 46102 | D8: =DATEDIF(B8,C8,"Y") -> 3 | E8: =DATEDIF(B8,C8,"YM") -> 2 | F8: =DATEDIF(B8,C8,"MD") -> 20 | G8: =C8-B8 -> 1175 | H8: 100 | I8: =G8*H8% -> 1175 | J8: =B8+I8 -> 46102 | K8: =DATEDIF(B8,J8,"Y") -> 3 | L8: =DATEDIF(B8,J8,"YM") -> 2 | M8: =DATEDIF(B8,J8,"MD") -> 20

Sheet นับวันใน-ตน.
A1: แปลง พศ เป็น คศ => | B1: 243523 | C1: =IF(AND(LEFT(B1,2)="29",MID(B1,4,1)="2"),LEFT(B1,2)&"/"&MID(B1,4,1)&"/"&RIGHT(B1,4)-543,EDATE(B1,-543*12)) -> 45196
A2: เลข ปชช | B2: ตน.ที่จะเลื่อน | C2: วัน เริ่มต้น | D2: วัน สิ้นสุด | E2: ปี | F2: เดือน | G2: วัน | H2: จำนวนวันทั้งหมด
A3: 1234567890001 | C3: 42005 | D3: 43101 | E3: =DATEDIF(C3,D3,"Y") -> 3 | F3: =DATEDIF(C3,D3,"YM") -> 0 | G3: =DATEDIF(C3,D3,"MD") -> 0 | H3: =D3-C3 -> 1096
A4: 1234567890002 | B4: นักทรัพยากรบุคคล | C4: 42005 | D4: 43101 | E4: =DATEDIF(C4,D4,"Y") -> 3 | F4: =DATEDIF(C4,D4,"YM") -> 0 | G4: =DATEDIF(C4,D4,"MD") -> 0 | H4: =D4-C4 -> 1096
A5: 1234567890003 | B5: นักทรัพยากรบุคคล | C5: 38353 | D5: 40909 | E5: =DATEDIF(C5,D5,"Y") -> 7 | F5: =DATEDIF(C5,D5,"YM") -> 0 | G5: =DATEDIF(C5,D5,"MD") -> 0 | H5: =D5-C5 -> 2556
A6: 1234567890004 | B6: นักทรัพยากรบุคคล | C6: 44197 | D6: 44927 | E6: =DATEDIF(C6,D6,"Y") -> 2 | F6: =DATEDIF(C6,D6,"YM") -> 0 | G6: =DATEDIF(C6,D6,"MD") -> 0 | H6: =D6-C6 -> 730

Sheet นับต่าง
A1: แปลง พศ เป็น คศ => | B1: 243523 | C1: =IF(AND(LEFT(B1,2)="29",MID(B1,4,1)="2"),LEFT(B1,2)&"/"&MID(B1,4,1)&"/"&RIGHT(B1,4)-543,EDATE(B1,-543*12)) -> 45196
A2: เลข ปชช | B2: ตน.เดิม | C2: กลุ่มงาน | D2: กอง | E2: กรม | F2: จังหวัด | G2: วัน เริ่มต้น | H2: วัน สิ้นสุด | I2: ปี | J2: เดือน | K2: วัน | L2: จำนวนวันทั้งหมด | M2: ตน.ใหม่ | N2: กลุ่มงาน | O2: กอง | P2: กรม | Q2: จังหวัด | R2: วัน เริ่มต้น | S2: วัน สิ้นสุด | T2: ปี | U2: เดือน | V2: วัน | W2: จำนวนวันทั้งหมด | X2: ต่างสายงาน | Y2: ต่างหน่วยงาน | Z2: ต่างพื้นที่ | AA2: ต่างลักษณะงาน | AB2: ครบ 3 ต่าง | AC2: วันที่ครบ 3 ต่าง
A3: 1234567890001 | B3: นักทรัพยากรบุคคล | C3: สรรหา | D3: กองบริหารทรัพยากรบุคคล | E3: สำนักงานปลัดกระทรวงยุติธรรม | F3: กรุงเทพ | G3: 42005 | H3: 43101 | I3: =DATEDIF(G3,H3,"Y") -> 3 | J3: =DATEDIF(G3,H3,"YM") -> 0 | K3: =DATEDIF(G3,H3,"MD") -> 0 | L3: =H3-G3 -> 1096 | M3: นักวิชาการยุติธรรม | P3: สำนักงานปลัดกระทรวงยุติธรรม | Q3: นนทบุรี | R3: 43101 | S3: 43466 | T3: =DATEDIF(R3,S3,"Y") -> 1 | U3: =DATEDIF(R3,S3,"YM") -> 0 | V3: =DATEDIF(R3,S3,"MD") -> 0 | W3: =S3-R3 -> 365 | X3: =_xlfn.IFS(AND(B3<>M3,AND(I3>=2,T3>=2)),2,AND(B3<>M3,OR(I3>=2,T3>=2)),1,TRUE,0) -> 1 | Y3: =_xlfn.IFS(X3>0,0,AND(OR(D3<>O3,E3<>P3),AND(I3>=2,T3>=2)),2,X3>0,0,AND(OR(D3<>O3,E3<>P3),OR(I3>=2,T3>=2)),1,TRUE,0) -> 0 | Z3: =_xlfn.IFS(OR(X3>0,Y3>0),0,AND(F3<>Q3,AND(I3>=2,T3>=2)),2,OR(X3>0,Y3>0),0,AND(F3<>Q3,OR(I3>=2,T3>=2)),1,TRUE,0) -> 0 | AA3: =_xlfn.IFS(OR(X3>0,Y3>0,Z3>0),0,AND(B3=M3,C3<>N3,AND(I3>=2,T3>=2)),2,AND(B3=M3,C3<>N3,OR(I3>=2,T3>=2)),1,AND(B3=M3,C3=N3,L3+W3>=730),1,TRUE,0) -> 0 | AB3: =_xlfn.IFS(A3<>A2,SUM(X3:AA3),A3=A2,SUM(X3:AA3)+AB2,TRUE,Check data) -> 1 | AC3: =IF(AB3>=3,S3,"")
A4: 1234567890001 | B4: นักทรัพยากรบุคคล | C4: ข้อมูล | D4: กองบริหารทรัพยากรบุคคล | E4: สำนักงานปลัดกระทรวงยุติธรรม | F4: กรุงเทพ | G4: 42005 | H4: 43101 | I4: =DATEDIF(G4,H4,"Y") -> 3 | J4: =DATEDIF(G4,H4,"YM") -> 0 | K4: =DATEDIF(G4,H4,"MD") -> 0 | L4: =H4-G4 -> 1096 | M4: นักทรัพยากรบุคคล | N4: สรรหา | O4: บริหารทรัพยากรบุคคล | Q4: กรุงเทพ | R4: 42005 | S4: 43101 | T4: =DATEDIF(R4,S4,"Y") -> 3 | U4: =DATEDIF(R4,S4,"YM") -> 0 | V4: =DATEDIF(R4,S4,"MD") -> 0 | W4: =S4-R4 -> 1096 | X4: =_xlfn.IFS(AND(B4<>M4,AND(I4>=2,T4>=2)),2,AND(B4<>M4,OR(I4>=2,T4>=2)),1,TRUE,0) -> 0 | Y4: =_xlfn.IFS(X4>0,0,AND(OR(D4<>O4,E4<>P4),AND(I4>=2,T4>=2)),2,X4>0,0,AND(OR(D4<>O4,E4<>P4),OR(I4>=2,T4>=2)),1,TRUE,0) -> 2 | Z4: =_xlfn.IFS(OR(X4>0,Y4>0),0,AND(F4<>Q4,AND(I4>=2,T4>=2)),2,OR(X4>0,Y4>0),0,AND(F4<>Q4,OR(I4>=2,T4>=2)),1,TRUE,0) -> 0 | AA4: =_xlfn.IFS(OR(X4>0,Y4>0,Z4>0),0,AND(B4=M4,C4<>N4,AND(I4>=2,T4>=2)),2,AND(B4=M4,C4<>N4,OR(I4>=2,T4>=2)),1,AND(B4=M4,C4=N4,L4+W4>=730),1,TRUE,0) -> 0 | AB4: =_xlfn.IFS(A4<>A3,SUM(X4:AA4),A4=A3,SUM(X4:AA4)+AB3,TRUE,Check data) -> 3 | AC4: =IF(AB4>=3,S4,"") -> 43101
A5: 1234567890001 | B5: นักทรัพยากรบุคคล | C5: ข้อมูล | D5: กองบริหารทรัพยากรบุคคล | E5: สำนักงานปลัดกระทรวงยุติธรรม | F5: กรุงเทพ | G5: 38353 | H5: 38718 | I5: =DATEDIF(G5,H5,"Y") -> 1 | J5: =DATEDIF(G5,H5,"YM") -> 0 | K5: =DATEDIF(G5,H5,"MD") -> 0 | L5: =H5-G5 -> 365 | M5: นักทรัพยากรบุคคล | N5: ข้อมูล | O5: บริหารทรัพยากรบุคคล | R5: 41640 | S5: 42005 | T5: =DATEDIF(R5,S5,"Y") -> 1 | U5: =DATEDIF(R5,S5,"YM") -> 0 | V5: =DATEDIF(R5,S5,"MD") -> 0 | W5: =S5-R5 -> 365 | X5: =_xlfn.IFS(AND(B5<>M5,AND(I5>=2,T5>=2)),2,AND(B5<>M5,OR(I5>=2,T5>=2)),1,TRUE,0) -> 0 | Y5: =_xlfn.IFS(X5>0,0,AND(OR(D5<>O5,E5<>P5),AND(I5>=2,T5>=2)),2,X5>0,0,AND(OR(D5<>O5,E5<>P5),OR(I5>=2,T5>=2)),1,TRUE,0) -> 0 | Z5: =_xlfn.IFS(OR(X5>0,Y5>0),0,AND(F5<>Q5,AND(I5>=2,T5>=2)),2,OR(X5>0,Y5>0),0,AND(F5<>Q5,OR(I5>=2,T5>=2)),1,TRUE,0) -> 0 | AA5: =_xlfn.IFS(OR(X5>0,Y5>0,Z5>0),0,AND(B5=M5,C5<>N5,AND(I5>=2,T5>=2)),2,AND(B5=M5,C5<>N5,OR(I5>=2,T5>=2)),1,AND(B5=M5,C5=N5,L5+W5>=730),1,TRUE,0) -> 1 | AB5: =_xlfn.IFS(A5<>A4,SUM(X5:AA5),A5=A4,SUM(X5:AA5)+AB4,TRUE,Check data) -> 4 | AC5: =IF(AB5>=3,S5,"") -> 42005
A6: 1234567890002 | I6: =DATEDIF(G6,H6,"Y") -> 0 | J6: =DATEDIF(G6,H6,"YM") -> 0 | K6: =DATEDIF(G6,H6,"MD") -> 0 | L6: =H6-G6 -> 0 | T6: =DATEDIF(R6,S6,"Y") -> 0 | U6: =DATEDIF(R6,S6,"YM") -> 0 | V6: =DATEDIF(R6,S6,"MD") -> 0 | W6: =S6-R6 -> 0 | X6: =_xlfn.IFS(AND(B6<>M6,AND(I6>=2,T6>=2)),2,AND(B6<>M6,OR(I6>=2,T6>=2)),1,TRUE,0) -> 0 | Y6: =_xlfn.IFS(X6>0,0,AND(OR(D6<>O6,E6<>P6),AND(I6>=2,T6>=2)),2,X6>0,0,AND(OR(D6<>O6,E6<>P6),OR(I6>=2,T6>=2)),1,TRUE,0) -> 0 | Z6: =_xlfn.IFS(OR(X6>0,Y6>0),0,AND(F6<>Q6,AND(I6>=2,T6>=2)),2,OR(X6>0,Y6>0),0,AND(F6<>Q6,OR(I6>=2,T6>=2)),1,TRUE,0) -> 0 | AA6: =_xlfn.IFS(OR(X6>0,Y6>0,Z6>0),0,AND(B6=M6,C6<>N6,AND(I6>=2,T6>=2)),2,AND(B6=M6,C6<>N6,OR(I6>=2,T6>=2)),1,AND(B6=M6,C6=N6,L6+W6>=730),1,TRUE,0) -> 0 | AB6: =_xlfn.IFS(A6<>A5,SUM(X6:AA6),A6=A5,SUM(X6:AA6)+AB5,TRUE,Check data) -> 0 | AC6: =IF(AB6>=3,S6,"")

Sheet เทียบ-ตน.
A1: แปลง พศ เป็น คศ => | B1: 243523 | C1: =IF(AND(LEFT(B1,2)="29",MID(B1,4,1)="2"),LEFT(B1,2)&"/"&MID(B1,4,1)&"/"&RIGHT(B1,4)-543,EDATE(B1,-543*12)) -> 45196
A2: เลข ปชช | B2: ตน.ปฏิบัติงาน | C2: เทียบตำแหน่ง | D2: ขอ เริ่มต้น | E2: ขอ สิ้นสุด | F2: ปี | G2: เดือน | H2: วัน | I2: จำนวนวันทั้งหมด | J2: เทียบ เริ่มต้น | K2: เทียบ สิ้นสุด | L2: ปี | M2: เดือน | N2: วัน | O2: จำนวนวันทั้งหมด
A3: 1234567890001 | B3: ผู้เชี่ยวชาญเฉพาะด้านบริหารทรัพยากรบุคคล | C3: อำนวยการ | D3: 43514 | E3: 45085 | F3: =DATEDIF(D3,E3,"Y") -> 4 | G3: =DATEDIF(D3,E3,"YM") -> 3 | H3: =DATEDIF(D3,E3,"MD") -> 21 | I3: =E3-D3 -> 1571 | J3: 43514 | K3: 45085 | L3: =DATEDIF(J3,K3,"Y") -> 4 | M3: =DATEDIF(J3,K3,"YM") -> 3 | N3: =DATEDIF(J3,K3,"MD") -> 21 | O3: =K3-J3 -> 1571
A4: 1234567890001 | C4: อำนวยการ | D4: 42005 | E4: 43101 | F4: =DATEDIF(D4,E4,"Y") -> 3 | G4: =DATEDIF(D4,E4,"YM") -> 0 | H4: =DATEDIF(D4,E4,"MD") -> 0 | I4: =E4-D4 -> 1096 | J4: 42005 | K4: 43101 | L4: =DATEDIF(J4,K4,"Y") -> 3 | M4: =DATEDIF(J4,K4,"YM") -> 0 | N4: =DATEDIF(J4,K4,"MD") -> 0 | O4: =K4-J4 -> 1096
A5: 1234567890001 | C5: อำนวยการ | D5: 38353 | E5: 40909 | F5: =DATEDIF(D5,E5,"Y") -> 7 | G5: =DATEDIF(D5,E5,"YM") -> 0 | H5: =DATEDIF(D5,E5,"MD") -> 0 | I5: =E5-D5 -> 2556 | J5: 38353 | K5: 40909 | L5: =DATEDIF(J5,K5,"Y") -> 7 | M5: =DATEDIF(J5,K5,"YM") -> 0 | N5: =DATEDIF(J5,K5,"MD") -> 0 | O5: =K5-J5 -> 2556
A6: 1234567890002 | C6: อำนวยการ | D6: 44197 | E6: 44927 | F6: =DATEDIF(D6,E6,"Y") -> 2 | G6: =DATEDIF(D6,E6,"YM") -> 0 | H6: =DATEDIF(D6,E6,"MD") -> 0 | I6: =E6-D6 -> 730 | J6: 44197 | K6: 44927 | L6: =DATEDIF(J6,K6,"Y") -> 2 | M6: =DATEDIF(J6,K6,"YM") -> 0 | N6: =DATEDIF(J6,K6,"MD") -> 0 | O6: =K6-J6 -> 730

Sheet นับวันใน-อต-อส
A1: แปลง พศ เป็น คศ => | B1: 243523 | C1: =IF(AND(LEFT(B1,2)="29",MID(B1,4,1)="2"),LEFT(B1,2)&"/"&MID(B1,4,1)&"/"&RIGHT(B1,4)-543,EDATE(B1,-543*12)) -> 45196
A2: เลข ปชช | B2: ตำแหน่ง | C2: วัน เริ่มต้น | D2: วัน สิ้นสุด | E2: ปี | F2: เดือน | G2: วัน | H2: จำนวนวันทั้งหมด
A3: 1234567890001 | C3: 42005 | D3: 43101 | E3: =DATEDIF(C3,D3,"Y") -> 3 | F3: =DATEDIF(C3,D3,"YM") -> 0 | G3: =DATEDIF(C3,D3,"MD") -> 0 | H3: =D3-C3 -> 1096
A4: 1234567890001 | B4: นักทรัพยากรบุคคล | C4: 42005 | D4: 43101 | E4: =DATEDIF(C4,D4,"Y") -> 3 | F4: =DATEDIF(C4,D4,"YM") -> 0 | G4: =DATEDIF(C4,D4,"MD") -> 0 | H4: =D4-C4 -> 1096
A5: 1234567890001 | B5: ผอ.บค | C5: 42622 | D5: 43513 | E5: =DATEDIF(C5,D5,"Y") -> 2 | F5: =DATEDIF(C5,D5,"YM") -> 5 | G5: =DATEDIF(C5,D5,"MD") -> 8 | H5: =D5-C5 -> 891
A6: 1234567890002 | B6: นักทรัพยากรบุคคล | C6: 44197 | D6: 44927 | E6: =DATEDIF(C6,D6,"Y") -> 2 | F6: =DATEDIF(C6,D6,"YM") -> 0 | G6: =DATEDIF(C6,D6,"MD") -> 0 | H6: =D6-C6 -> 730

Sheet to-K2
B1: วันปิดรับสมัคร | C1: =TODAY() -> 46102 | E1: แปลง พศ เป็น คศ => | F1: 243523 | G1: =IF(AND(LEFT(F1,2)="29",MID(F1,4,1)="2"),LEFT(F1,2)&"/"&MID(F1,4,1)&"/"&RIGHT(F1,4)-543,EDATE(F1,-543*12)) -> 45196
A2: ลำดับที่ | B2: เลข ปชช. | C2: ชื่อ - นามสกุล | D2: วันบรรจุ | E2: ตำแหน่งปัจจุบัน | F2: ประเภทระดับปัจจุบัน | G2: วันเข้าสู่ระดับปัจจุบัน | H2: ปี | I2: เดือน | J2: วัน | K2: ตำแหน่ง ก่อนปัจจุบัน | L2: ประเภทระดับ ก่อนปัจจุบัน | M2: วันเข้าสู่ระดับก่อนปัจจุบัน | N2: ปี | O2: เดือน | P2: วัน | Q2: ระดับการศึกษา | R2: ตน.ที่จะเลื่อน | S2: ระดับที่จะเลื่อน | T2: ประวัติสายงาน | U2: จำนวนวัน ใน ตน.ที่จะเลื่อน | V2: เกื้อกูล จำนวนวัน | W2: จำนวนวัน ตน.ที่จะเลื่อน + เกื้อกูล | X2: วันที่เริ่มนับ | Y2: วันที่มีคุณสมบัติ | Z2: จำนวนวันที่เหลือ | AA2: สถานะ
E3: นักวิชาการยุติธรรม | F3: K1 | G3: 1/12/2019 | H3: =DATEDIF(G3,$C$1,"Y") -> 6 | I3: =DATEDIF(G3,$C$1,"YM") -> 3 | J3: =DATEDIF(G3,$C$1,"MD") -> 20 | K3: นักวิชาการยุติธรรม | L3: K1 | M3: 1/12/2019 | N3: =DATEDIF(M3,G3,"Y") -> 0 | O3: =DATEDIF(M3,G3,"YM") -> 0 | P3: =DATEDIF(M3,G3,"MD") -> 0 | Q3: ป.ตรี | R3: นักวิชาการยุติธรรม | S3: K2 | T3: 1 | U3: =_xlfn.IFS(AND(T3=1,K3=R3,E3=R3),$C$1-M3,AND(T3=2,K3=R3,E3<>R3),G3-M3,AND(T3=2,K3<>R3,E3=R3),$C$1-G3,AND(K3<>R3,E3<>R3),0,T3>2,SUMIFS('นับวันใน-ตน.'!H:H,'นับวันใน-ตน.'!A:A,B3,'นับวันใน-ตน.'!B:B,R3),TRUE,0) -> 2302 | V3: =SUMIF(นับเกื้อกูล!A:A,B3,นับเกื้อกูล!I:I) -> 0 | W3: =U3+V3 -> 2302 | X3: =IF(W3>0,$C$1-W3,"Check Data") -> 43800 | Y3: =_xlfn.IFS(Q3="ป.ตรี",EDATE(X3,12*6),Q3="ป.ตรี 5 ปี",EDATE(X3,12*5),Q3="ป.ตรี 6 ปี",EDATE(X3,12*4),Q3="ป.โท",EDATE(X3,12*4),Q3="ป.เอก",EDATE(X3,12*2),TRUE,"Check Data") -> 45992 | Z3: =IF(TODAY()>Y3,Y3-TODAY(),DATEDIF(TODAY(),Y3,"d")) -> -110 | AA3: =_xlfn.IFS(Z3>30,"ยังไม่ถึงเกณฑ์",Z3>0,"ใกล้ถึงเกณฑ์",Z3=0,"ถึงเกณฑ์",Z3<0,"ถึงเกณฑ์นานแล้ว") -> ถึงเกณฑ์นานแล้ว
E4: นักทรัพยากรบุคคล | F4: K1 | G4: 1/6/2012 | H4: =DATEDIF(G4,$C$1,"Y") -> 13 | I4: =DATEDIF(G4,$C$1,"YM") -> 9 | J4: =DATEDIF(G4,$C$1,"MD") -> 20 | K4: นักทรัพยากรบุคคล | L4: K1 | M4: 1/6/2012 | N4: =DATEDIF(M4,G4,"Y") -> 0 | O4: =DATEDIF(M4,G4,"YM") -> 0 | P4: =DATEDIF(M4,G4,"MD") -> 0 | Q4: ป.ตรี | R4: นักทรัพยากรบุคคล | S4: K2 | T4: 1 | U4: =_xlfn.IFS(AND(T4=1,K4=R4,E4=R4),$C$1-M4,AND(T4=2,K4=R4,E4<>R4),G4-M4,AND(T4=2,K4<>R4,E4=R4),$C$1-G4,AND(K4<>R4,E4<>R4),0,T4>2,SUMIFS('นับวันใน-ตน.'!H:H,'นับวันใน-ตน.'!A:A,B4,'นับวันใน-ตน.'!B:B,R4),TRUE,0) -> 5041 | V4: =SUMIF(นับเกื้อกูล!A:A,B4,นับเกื้อกูล!I:I) -> 0 | W4: =U4+V4 -> 5041 | X4: =IF(W4>0,$C$1-W4,"Check Data") -> 41061 | Y4: =_xlfn.IFS(Q4="ป.ตรี",EDATE(X4,12*6),Q4="ป.ตรี 5 ปี",EDATE(X4,12*5),Q4="ป.ตรี 6 ปี",EDATE(X4,12*4),Q4="ป.โท",EDATE(X4,12*4),Q4="ป.เอก",EDATE(X4,12*2),TRUE,"Check Data") -> 43252 | Z4: =IF(TODAY()>Y4,Y4-TODAY(),DATEDIF(TODAY(),Y4,"d")) -> -2850 | AA4: =_xlfn.IFS(Z4>30,"ยังไม่ถึงเกณฑ์",Z4>0,"ใกล้ถึงเกณฑ์",Z4=0,"ถึงเกณฑ์",Z4<0,"ถึงเกณฑ์นานแล้ว") -> ถึงเกณฑ์นานแล้ว
B5: 1234567890002 | E5: นักวิชาการยุติธรรม | F5: K1 | G5: 1/1/2023 | H5: =DATEDIF(G5,$C$1,"Y") -> 3 | I5: =DATEDIF(G5,$C$1,"YM") -> 2 | J5: =DATEDIF(G5,$C$1,"MD") -> 20 | K5: นักทรัพยากรบุคคล | L5: K1 | M5: 1/1/2021 | N5: =DATEDIF(M5,G5,"Y") -> 2 | O5: =DATEDIF(M5,G5,"YM") -> 0 | P5: =DATEDIF(M5,G5,"MD") -> 0 | Q5: ป.โท | R5: นักทรัพยากรบุคคล | S5: K2 | T5: 2 | U5: =_xlfn.IFS(AND(T5=1,K5=R5,E5=R5),$C$1-M5,AND(T5=2,K5=R5,E5<>R5),G5-M5,AND(T5=2,K5<>R5,E5=R5),$C$1-G5,AND(K5<>R5,E5<>R5),0,T5>2,SUMIFS('นับวันใน-ตน.'!H:H,'นับวันใน-ตน.'!A:A,B5,'นับวันใน-ตน.'!B:B,R5),TRUE,0) -> 730 | V5: =SUMIF(นับเกื้อกูล!A:A,B5,นับเกื้อกูล!I:I) -> 548 | W5: =U5+V5 -> 1278 | X5: =IF(W5>0,$C$1-W5,"Check Data") -> 44824 | Y5: =_xlfn.IFS(Q5="ป.ตรี",EDATE(X5,12*6),Q5="ป.ตรี 5 ปี",EDATE(X5,12*5),Q5="ป.ตรี 6 ปี",EDATE(X5,12*4),Q5="ป.โท",EDATE(X5,12*4),Q5="ป.เอก",EDATE(X5,12*2),TRUE,"Check Data") -> 46285 | Z5: =IF(TODAY()>Y5,Y5-TODAY(),DATEDIF(TODAY(),Y5,"d")) -> 183 | AA5: =_xlfn.IFS(Z5>30,"ยังไม่ถึงเกณฑ์",Z5>0,"ใกล้ถึงเกณฑ์",Z5=0,"ถึงเกณฑ์",Z5<0,"ถึงเกณฑ์นานแล้ว") -> ยังไม่ถึงเกณฑ์
E6: นิติกร | F6: K1 | G6: 1/12/2019 | H6: =DATEDIF(G6,$C$1,"Y") -> 6 | I6: =DATEDIF(G6,$C$1,"YM") -> 3 | J6: =DATEDIF(G6,$C$1,"MD") -> 20 | K6: นิติกร | N6: =DATEDIF(M6,G6,"Y") -> 119 | O6: =DATEDIF(M6,G6,"YM") -> 11 | P6: =DATEDIF(M6,G6,"MD") -> 1 | Q6: ป.เอก | R6: นิติกร | S6: K2 | T6: 1 | U6: =_xlfn.IFS(AND(T6=1,K6=R6,E6=R6),$C$1-M6,AND(T6=2,K6=R6,E6<>R6),G6-M6,AND(T6=2,K6<>R6,E6=R6),$C$1-G6,AND(K6<>R6,E6<>R6),0,T6>2,SUMIFS('นับวันใน-ตน.'!H:H,'นับวันใน-ตน.'!A:A,B6,'นับวันใน-ตน.'!B:B,R6),TRUE,0) -> 46102 | V6: =SUMIF(นับเกื้อกูล!A:A,B6,นับเกื้อกูล!I:I) -> 0 | W6: =U6+V6 -> 46102 | X6: =IF(W6>0,$C$1-W6,"Check Data") -> 0 | Y6: =_xlfn.IFS(Q6="ป.ตรี",EDATE(X6,12*6),Q6="ป.ตรี 5 ปี",EDATE(X6,12*5),Q6="ป.ตรี 6 ปี",EDATE(X6,12*4),Q6="ป.โท",EDATE(X6,12*4),Q6="ป.เอก",EDATE(X6,12*2),TRUE,"Check Data") -> 731 | Z6: =IF(TODAY()>Y6,Y6-TODAY(),DATEDIF(TODAY(),Y6,"d")) -> -45371 | AA6: =_xlfn.IFS(Z6>30,"ยังไม่ถึงเกณฑ์",Z6>0,"ใกล้ถึงเกณฑ์",Z6=0,"ถึงเกณฑ์",Z6<0,"ถึงเกณฑ์นานแล้ว") -> ถึงเกณฑ์นานแล้ว
U7: =_xlfn.IFS(AND(T7=1,K7=R7,E7=R7),$C$1-M7,AND(T7=2,K7=R7,E7<>R7),G7-M7,AND(T7=2,K7<>R7,E7=R7),$C$1-G7,AND(K7<>R7,E7<>R7),0,T7>2,SUMIFS('นับวันใน-ตน.'!H:H,'นับวันใน-ตน.'!A:A,B7,'นับวันใน-ตน.'!B:B,R7),TRUE,0) -> 0 | V7: =SUMIF(นับเกื้อกูล!A:A,B7,นับเกื้อกูล!I:I) -> 0 | W7: =U7+V7 -> 0 | X7: =IF(W7>0,$C$1-W7,"Check Data") -> Check Data | Y7: =_xlfn.IFS(Q7="ป.ตรี",EDATE(X7,12*6),Q7="ป.ตรี 5 ปี",EDATE(X7,12*5),Q7="ป.ตรี 6 ปี",EDATE(X7,12*4),Q7="ป.โท",EDATE(X7,12*4),Q7="ป.เอก",EDATE(X7,12*2),TRUE,"Check Data") -> Check Data

Sheet to-K3
B1: วันปิดรับสมัคร | C1: 45170 | E1: แปลง พศ เป็น คศ => | F1: 241346 | G1: =IF(AND(LEFT(F1,2)="29",MID(F1,4,1)="2"),LEFT(F1,2)&"/"&MID(F1,4,1)&"/"&RIGHT(F1,4)-543,EDATE(F1,-543*12)) -> 43019
A2: ลำดับที่ | B2: เลข ปชช. | C2: ชื่อ - นามสกุล | D2: วันบรรจุ | E2: ตำแหน่งปัจจุบัน | F2: ประเภทระดับปัจจุบัน | G2: วันเข้าสู่ระดับปัจจุบัน | H2: ปี | I2: เดือน | J2: วัน | K2: ตำแหน่ง ก่อนปัจจุบัน | L2: ประเภทระดับ ก่อนปัจจุบัน | M2: วันเข้าสู่ระดับ ก่อนปัจจุบัน | N2: ปี | O2: เดือน | P2: วัน | Q2: ระดับการศึกษา | R2: ตน.ที่จะเลื่อน | S2: ระดับที่จะเลื่อน | T2: ประวัติสายงาน | U2: จำนวนวัน ใน ตน.ที่จะเลื่อน | V2: เกื้อกูล จำนวนวัน | W2: จำนวนวัน ตน.ที่จะเลื่อน + เกื้อกูล | X2: วันที่เริ่มนับ | Y2: วันที่ดำรงตำแหน่ง ชก 4 ปี | Z2: วันที่มีคุณสมบัติในสายงาน | AA2: วันที่มีคุณสมบัติ ชพ | AB2: จำนวนวันที่เหลือ | AC2: สถานะ | AD2: หมายเหตุ
D3: 15/3/2012 | E3: นักทรัพยากรบุคคล | F3: K2 | G3: 27/12/2022 | H3: =DATEDIF(G3,$C$1,"Y") -> 0 | I3: =DATEDIF(G3,$C$1,"YM") -> 8 | J3: =DATEDIF(G3,$C$1,"MD") -> 5 | K3: นักทรัพยากรบุคคล | L3: K1 | M3: 15/3/2012 | N3: =DATEDIF(M3,G3,"Y") -> 10 | O3: =DATEDIF(M3,G3,"YM") -> 9 | P3: =DATEDIF(M3,G3,"MD") -> 12 | Q3: ป.โท | R3: นักทรัพยากรบุคคล | S3: K3 | T3: 1 | U3: =_xlfn.IFS(AND(T3=1,K3=R3,E3=R3),$C$1-M3,AND(T3=2,K3=R3,E3<>R3),G3-M3,AND(T3=2,K3<>R3,E3=R3),$C$1-G3,AND(K3<>R3,E3<>R3),0,T3>2,SUMIFS('นับวันใน-ตน.'!H:H,'นับวันใน-ตน.'!A:A,B3,'นับวันใน-ตน.'!B:B,R3),TRUE,0) -> 4187 | V3: =SUMIF(นับเกื้อกูล!A:A,B3,นับเกื้อกูล!I:I) -> 0 | W3: =U3+V3 -> 4187 | X3: =IF(W3>0,$C$1-W3,"Check Data") -> 40983 | Y3: =EDATE(G3,12*4) -> 46383 | Z3: =IFERROR(_xlfn.IFS(Q3="ป.ตรี",EDATE(X3,12*10),Q3="ป.ตรี 5 ปี",EDATE(X3,12*9),Q3="ป.ตรี 6 ปี",EDATE(X3,12*8),Q3="ป.โท",EDATE(X3,12*8),Q3="ป.เอก",EDATE(X3,12*6),TRUE,"Check Data"),"Check Data") -> 43905 | AA3: =IF(Y3>Z3,Y3,Z3) -> 46383 | AB3: =_xlfn.IFS(AND(TODAY()>Y3,Y3>Z3),Y3-TODAY(),AND(TODAY()>Z3,Z3>Y3),Z3-TODAY(),AND(TODAY()<Y3,Y3>Z3),DATEDIF(TODAY(),Y3,"d"),AND(TODAY()<Z3,Z3>Y3),DATEDIF(TODAY(),Z3,"d"),Y3=Z3,DATEDIF(TODAY(),Y3,"d")) -> 281 | AC3: =_xlfn.IFS(AB3>30,"ยังไม่ถึงเกณฑ์",AB3>0,"ใกล้ถึงเกณฑ์",AB3=0,"ถึงเกณฑ์",AB3<0,"ถึงเกณฑ์นานแล้ว") -> ยังไม่ถึงเกณฑ์
D4: 14/10/2016 | E4: นักทรัพยากรบุคคล | F4: K2 | G4: 10/08/2022 | H4: =DATEDIF(G4,$C$1,"Y") -> 1 | I4: =DATEDIF(G4,$C$1,"YM") -> 0 | J4: =DATEDIF(G4,$C$1,"MD") -> 22 | K4: นักทรัพยากรบุคคล | L4: K1 | M4: 14/10/2016 | N4: =DATEDIF(M4,G4,"Y") -> 5 | O4: =DATEDIF(M4,G4,"YM") -> 9 | P4: =DATEDIF(M4,G4,"MD") -> 27 | Q4: ป.โท | R4: นักทรัพยากรบุคคล | S4: K3 | T4: 1 | U4: =_xlfn.IFS(AND(T4=1,K4=R4,E4=R4),$C$1-M4,AND(T4=2,K4=R4,E4<>R4),G4-M4,AND(T4=2,K4<>R4,E4=R4),$C$1-G4,AND(K4<>R4,E4<>R4),0,T4>2,SUMIFS('นับวันใน-ตน.'!H:H,'นับวันใน-ตน.'!A:A,B4,'นับวันใน-ตน.'!B:B,R4),TRUE,0) -> 2513 | V4: =SUMIF(นับเกื้อกูล!A:A,B4,นับเกื้อกูล!I:I) -> 0 | W4: =U4+V4 -> 2513 | X4: =IF(W4>0,$C$1-W4,"Check Data") -> 42657 | Y4: =EDATE(G4,12*4) -> 46244 | Z4: =IFERROR(_xlfn.IFS(Q4="ป.ตรี",EDATE(X4,12*10),Q4="ป.ตรี 5 ปี",EDATE(X4,12*9),Q4="ป.ตรี 6 ปี",EDATE(X4,12*8),Q4="ป.โท",EDATE(X4,12*8),Q4="ป.เอก",EDATE(X4,12*6),TRUE,"Check Data"),"Check Data") -> 45579 | AA4: =IF(Y4>Z4,Y4,Z4) -> 46244 | AB4: =_xlfn.IFS(AND(TODAY()>Y4,Y4>Z4),Y4-TODAY(),AND(TODAY()>Z4,Z4>Y4),Z4-TODAY(),AND(TODAY()<Y4,Y4>Z4),DATEDIF(TODAY(),Y4,"d"),AND(TODAY()<Z4,Z4>Y4),DATEDIF(TODAY(),Z4,"d"),Y4=Z4,DATEDIF(TODAY(),Y4,"d")) -> 142 | AC4: =_xlfn.IFS(AB4>30,"ยังไม่ถึงเกณฑ์",AB4>0,"ใกล้ถึงเกณฑ์",AB4=0,"ถึงเกณฑ์",AB4<0,"ถึงเกณฑ์นานแล้ว") -> ยังไม่ถึงเกณฑ์
D5: 4/3/2016 | E5: นักทรัพยากรบุคคล | F5: K2 | G5: 9/3/2020 | H5: =DATEDIF(G5,$C$1,"Y") -> 3 | I5: =DATEDIF(G5,$C$1,"YM") -> 5 | J5: =DATEDIF(G5,$C$1,"MD") -> 23 | K5: นักทรัพยากรบุคคล | L5: K1 | M5: 4/3/2016 | N5: =DATEDIF(M5,G5,"Y") -> 4 | O5: =DATEDIF(M5,G5,"YM") -> 0 | P5: =DATEDIF(M5,G5,"MD") -> 5 | Q5: ป.โท | R5: นักทรัพยากรบุคคล | S5: K3 | T5: 1 | U5: =_xlfn.IFS(AND(T5=1,K5=R5,E5=R5),$C$1-M5,AND(T5=2,K5=R5,E5<>R5),G5-M5,AND(T5=2,K5<>R5,E5=R5),$C$1-G5,AND(K5<>R5,E5<>R5),0,T5>2,SUMIFS('นับวันใน-ตน.'!H:H,'นับวันใน-ตน.'!A:A,B5,'นับวันใน-ตน.'!B:B,R5),TRUE,0) -> 2737 | V5: =SUMIF(นับเกื้อกูล!A:A,B5,นับเกื้อกูล!I:I) -> 0 | W5: =U5+V5 -> 2737 | X5: =IF(W5>0,$C$1-W5,"Check Data") -> 42433 | Y5: =EDATE(G5,12*4) -> 45360 | Z5: =IFERROR(_xlfn.IFS(Q5="ป.ตรี",EDATE(X5,12*10),Q5="ป.ตรี 5 ปี",EDATE(X5,12*9),Q5="ป.ตรี 6 ปี",EDATE(X5,12*8),Q5="ป.โท",EDATE(X5,12*8),Q5="ป.เอก",EDATE(X5,12*6),TRUE,"Check Data"),"Check Data") -> 45355 | AA5: =IF(Y5>Z5,Y5,Z5) -> 45360 | AB5: =_xlfn.IFS(AND(TODAY()>Y5,Y5>Z5),Y5-TODAY(),AND(TODAY()>Z5,Z5>Y5),Z5-TODAY(),AND(TODAY()<Y5,Y5>Z5),DATEDIF(TODAY(),Y5,"d"),AND(TODAY()<Z5,Z5>Y5),DATEDIF(TODAY(),Z5,"d"),Y5=Z5,DATEDIF(TODAY(),Y5,"d")) -> -742 | AC5: =_xlfn.IFS(AB5>30,"ยังไม่ถึงเกณฑ์",AB5>0,"ใกล้ถึงเกณฑ์",AB5=0,"ถึงเกณฑ์",AB5<0,"ถึงเกณฑ์นานแล้ว") -> ถึงเกณฑ์นานแล้ว
D6: 13/7/2012 | E6: นักทรัพยากรบุคคล | F6: K2 | G6: 28/3/2018 | H6: =DATEDIF(G6,$C$1,"Y") -> 5 | I6: =DATEDIF(G6,$C$1,"YM") -> 5 | J6: =DATEDIF(G6,$C$1,"MD") -> 4 | K6: นักทรัพยากรบุคคล | L6: K1 | M6: 13/7/2012 | N6: =DATEDIF(M6,G6,"Y") -> 5 | O6: =DATEDIF(M6,G6,"YM") -> 8 | P6: =DATEDIF(M6,G6,"MD") -> 15 | Q6: ป.โท | R6: นักทรัพยากรบุคคล | S6: K3 | T6: 1 | U6: =_xlfn.IFS(AND(T6=1,K6=R6,E6=R6),$C$1-M6,AND(T6=2,K6=R6,E6<>R6),G6-M6,AND(T6=2,K6<>R6,E6=R6),$C$1-G6,AND(K6<>R6,E6<>R6),0,T6>2,SUMIFS('นับวันใน-ตน.'!H:H,'นับวันใน-ตน.'!A:A,B6,'นับวันใน-ตน.'!B:B,R6),TRUE,0) -> 4067 | V6: =SUMIF(นับเกื้อกูล!A:A,B6,นับเกื้อกูล!I:I) -> 0 | W6: =U6+V6 -> 4067 | X6: =IF(W6>0,$C$1-W6,"Check Data") -> 41103 | Y6: =EDATE(G6,12*4) -> 44648 | Z6: =IFERROR(_xlfn.IFS(Q6="ป.ตรี",EDATE(X6,12*10),Q6="ป.ตรี 5 ปี",EDATE(X6,12*9),Q6="ป.ตรี 6 ปี",EDATE(X6,12*8),Q6="ป.โท",EDATE(X6,12*8),Q6="ป.เอก",EDATE(X6,12*6),TRUE,"Check Data"),"Check Data") -> 44025 | AA6: =IF(Y6>Z6,Y6,Z6) -> 44648 | AB6: =_xlfn.IFS(AND(TODAY()>Y6,Y6>Z6),Y6-TODAY(),AND(TODAY()>Z6,Z6>Y6),Z6-TODAY(),AND(TODAY()<Y6,Y6>Z6),DATEDIF(TODAY(),Y6,"d"),AND(TODAY()<Z6,Z6>Y6),DATEDIF(TODAY(),Z6,"d"),Y6=Z6,DATEDIF(TODAY(),Y6,"d")) -> -1454 | AC6: =_xlfn.IFS(AB6>30,"ยังไม่ถึงเกณฑ์",AB6>0,"ใกล้ถึงเกณฑ์",AB6=0,"ถึงเกณฑ์",AB6<0,"ถึงเกณฑ์นานแล้ว") -> ถึงเกณฑ์นานแล้ว
D7: 28/7/2006 | E7: นักทรัพยากรบุคคล | F7: K2 | G7: 27/1/2014 | H7: =DATEDIF(G7,$C$1,"Y") -> 9 | I7: =DATEDIF(G7,$C$1,"YM") -> 7 | J7: =DATEDIF(G7,$C$1,"MD") -> 5 | K7: นักทรัพยากรบุคคล | L7: K1 | M7: 28/7/2006 | N7: =DATEDIF(M7,G7,"Y") -> 7 | O7: =DATEDIF(M7,G7,"YM") -> 5 | P7: =DATEDIF(M7,G7,"MD") -> 30 | Q7: ป.โท | R7: นักทรัพยากรบุคคล | S7: K3 | T7: 1 | U7: =_xlfn.IFS(AND(T7=1,K7=R7,E7=R7),$C$1-M7,AND(T7=2,K7=R7,E7<>R7),G7-M7,AND(T7=2,K7<>R7,E7=R7),$C$1-G7,AND(K7<>R7,E7<>R7),0,T7>2,SUMIFS('นับวันใน-ตน.'!H:H,'นับวันใน-ตน.'!A:A,B7,'นับวันใน-ตน.'!B:B,R7),TRUE,0) -> 6244 | V7: =SUMIF(นับเกื้อกูล!A:A,B7,นับเกื้อกูล!I:I) -> 0 | W7: =U7+V7 -> 6244 | X7: =IF(W7>0,$C$1-W7,"Check Data") -> 38926 | Y7: =EDATE(G7,12*4) -> 43127 | Z7: =IFERROR(_xlfn.IFS(Q7="ป.ตรี",EDATE(X7,12*10),Q7="ป.ตรี 5 ปี",EDATE(X7,12*9),Q7="ป.ตรี 6 ปี",EDATE(X7,12*8),Q7="ป.โท",EDATE(X7,12*8),Q7="ป.เอก",EDATE(X7,12*6),TRUE,"Check Data"),"Check Data") -> 41848 | AA7: =IF(Y7>Z7,Y7,Z7) -> 43127 | AB7: =_xlfn.IFS(AND(TODAY()>Y7,Y7>Z7),Y7-TODAY(),AND(TODAY()>Z7,Z7>Y7),Z7-TODAY(),AND(TODAY()<Y7,Y7>Z7),DATEDIF(TODAY(),Y7,"d"),AND(TODAY()<Z7,Z7>Y7),DATEDIF(TODAY(),Z7,"d"),Y7=Z7,DATEDIF(TODAY(),Y7,"d")) -> -2975 | AC7: =_xlfn.IFS(AB7>30,"ยังไม่ถึงเกณฑ์",AB7>0,"ใกล้ถึงเกณฑ์",AB7=0,"ถึงเกณฑ์",AB7<0,"ถึงเกณฑ์นานแล้ว") -> ถึงเกณฑ์นานแล้ว
D8: 1/10/2015 | E8: นักทรัพยากรบุคคล | F8: K2 | G8: 1/10/2019 | H8: =DATEDIF(G8,$C$1,"Y") -> 3 | I8: =DATEDIF(G8,$C$1,"YM") -> 11 | J8: =DATEDIF(G8,$C$1,"MD") -> 0 | K8: นักทรัพยากรบุคคล | L8: K1 | M8: 1/10/2015 | N8: =DATEDIF(M8,G8,"Y") -> 4 | O8: =DATEDIF(M8,G8,"YM") -> 0 | P8: =DATEDIF(M8,G8,"MD") -> 0 | Q8: ป.โท | R8: นักทรัพยากรบุคคล | S8: K3 | T8: 1 | U8: =_xlfn.IFS(AND(T8=1,K8=R8,E8=R8),$C$1-M8,AND(T8=2,K8=R8,E8<>R8),G8-M8,AND(T8=2,K8<>R8,E8=R8),$C$1-G8,AND(K8<>R8,E8<>R8),0,T8>2,SUMIFS('นับวันใน-ตน.'!H:H,'นับวันใน-ตน.'!A:A,B8,'นับวันใน-ตน.'!B:B,R8),TRUE,0) -> 2892 | V8: =SUMIF(นับเกื้อกูล!A:A,B8,นับเกื้อกูล!I:I) -> 0 | W8: =U8+V8 -> 2892 | X8: =IF(W8>0,$C$1-W8,"Check Data") -> 42278 | Y8: =EDATE(G8,12*4) -> 45200 | Z8: =IFERROR(_xlfn.IFS(Q8="ป.ตรี",EDATE(X8,12*10),Q8="ป.ตรี 5 ปี",EDATE(X8,12*9),Q8="ป.ตรี 6 ปี",EDATE(X8,12*8),Q8="ป.โท",EDATE(X8,12*8),Q8="ป.เอก",EDATE(X8,12*6),TRUE,"Check Data"),"Check Data") -> 45200 | AA8: =IF(Y8>Z8,Y8,Z8) -> 45200 | AB8: =_xlfn.IFS(AND(TODAY()>Y8,Y8>Z8),Y8-TODAY(),AND(TODAY()>Z8,Z8>Y8),Z8-TODAY(),AND(TODAY()<Y8,Y8>Z8),DATEDIF(TODAY(),Y8,"d"),AND(TODAY()<Z8,Z8>Y8),DATEDIF(TODAY(),Z8,"d"),Y8=Z8,DATEDIF(TODAY(),Y8,"d")) -> #NUM! | AC8: =_xlfn.IFS(AB8>30,"ยังไม่ถึงเกณฑ์",AB8>0,"ใกล้ถึงเกณฑ์",AB8=0,"ถึงเกณฑ์",AB8<0,"ถึงเกณฑ์นานแล้ว") -> #NUM!
D9: 15/10/2012 | E9: นักทรัพยากรบุคคล | F9: K2 | G9: 14/8/2020 | H9: =DATEDIF(G9,$C$1,"Y") -> 3 | I9: =DATEDIF(G9,$C$1,"YM") -> 0 | J9: =DATEDIF(G9,$C$1,"MD") -> 18 | K9: นักทรัพยากรบุคคล | L9: K1 | M9: 15/10/2012 | N9: =DATEDIF(M9,G9,"Y") -> 7 | O9: =DATEDIF(M9,G9,"YM") -> 9 | P9: =DATEDIF(M9,G9,"MD") -> 30 | Q9: ป.โท | R9: นักทรัพยากรบุคคล | S9: K3 | T9: 1 | U9: =_xlfn.IFS(AND(T9=1,K9=R9,E9=R9),$C$1-M9,AND(T9=2,K9=R9,E9<>R9),G9-M9,AND(T9=2,K9<>R9,E9=R9),$C$1-G9,AND(K9<>R9,E9<>R9),0,T9>2,SUMIFS('นับวันใน-ตน.'!H:H,'นับวันใน-ตน.'!A:A,B9,'นับวันใน-ตน.'!B:B,R9),TRUE,0) -> 3973 | V9: =SUMIF(นับเกื้อกูล!A:A,B9,นับเกื้อกูล!I:I) -> 0 | W9: =U9+V9 -> 3973 | X9: =IF(W9>0,$C$1-W9,"Check Data") -> 41197 | Y9: =EDATE(G9,12*4) -> 45518 | Z9: =IFERROR(_xlfn.IFS(Q9="ป.ตรี",EDATE(X9,12*10),Q9="ป.ตรี 5 ปี",EDATE(X9,12*9),Q9="ป.ตรี 6 ปี",EDATE(X9,12*8),Q9="ป.โท",EDATE(X9,12*8),Q9="ป.เอก",EDATE(X9,12*6),TRUE,"Check Data"),"Check Data") -> 44119 | AA9: =IF(Y9>Z9,Y9,Z9) -> 45518 | AB9: =_xlfn.IFS(AND(TODAY()>Y9,Y9>Z9),Y9-TODAY(),AND(TODAY()>Z9,Z9>Y9),Z9-TODAY(),AND(TODAY()<Y9,Y9>Z9),DATEDIF(TODAY(),Y9,"d"),AND(TODAY()<Z9,Z9>Y9),DATEDIF(TODAY(),Z9,"d"),Y9=Z9,DATEDIF(TODAY(),Y9,"d")) -> -584 | AC9: =_xlfn.IFS(AB9>30,"ยังไม่ถึงเกณฑ์",AB9>0,"ใกล้ถึงเกณฑ์",AB9=0,"ถึงเกณฑ์",AB9<0,"ถึงเกณฑ์นานแล้ว") -> ถึงเกณฑ์นานแล้ว
D10: 16/1/2009 | E10: นักทรัพยากรบุคคล | F10: K2 | G10: 19/10/2022 | H10: =DATEDIF(G10,$C$1,"Y") -> 0 | I10: =DATEDIF(G10,$C$1,"YM") -> 10 | J10: =DATEDIF(G10,$C$1,"MD") -> 13 | K10: นักทรัพยากรบุคคล | L10: K1 | M10: 16/1/2009 | N10: =DATEDIF(M10,G10,"Y") -> 13 | O10: =DATEDIF(M10,G10,"YM") -> 9 | P10: =DATEDIF(M10,G10,"MD") -> 3 | Q10: ป.โท | R10: นักทรัพยากรบุคคล | S10: K3 | T10: 1 | U10: =_xlfn.IFS(AND(T10=1,K10=R10,E10=R10),$C$1-M10,AND(T10=2,K10=R10,E10<>R10),G10-M10,AND(T10=2,K10<>R10,E10=R10),$C$1-G10,AND(K10<>R10,E10<>R10),0,T10>2,SUMIFS('นับวันใน-ตน.'!H:H,'นับวันใน-ตน.'!A:A,B10,'นับวันใน-ตน.'!B:B,R10),TRUE,0) -> 5341 | V10: =SUMIF(นับเกื้อกูล!A:A,B10,นับเกื้อกูล!I:I) -> 0 | W10: =U10+V10 -> 5341 | X10: =IF(W10>0,$C$1-W10,"Check Data") -> 39829 | Y10: =EDATE(G10,12*4) -> 46314 | Z10: =IFERROR(_xlfn.IFS(Q10="ป.ตรี",EDATE(X10,12*10),Q10="ป.ตรี 5 ปี",EDATE(X10,12*9),Q10="ป.ตรี 6 ปี",EDATE(X10,12*8),Q10="ป.โท",EDATE(X10,12*8),Q10="ป.เอก",EDATE(X10,12*6),TRUE,"Check Data"),"Check Data") -> 42751 | AA10: =IF(Y10>Z10,Y10,Z10) -> 46314 | AB10: =_xlfn.IFS(AND(TODAY()>Y10,Y10>Z10),Y10-TODAY(),AND(TODAY()>Z10,Z10>Y10),Z10-TODAY(),AND(TODAY()<Y10,Y10>Z10),DATEDIF(TODAY(),Y10,"d"),AND(TODAY()<Z10,Z10>Y10),DATEDIF(TODAY(),Z10,"d"),Y10=Z10,DATEDIF(TODAY(),Y10,"d")) -> 212 | AC10: =_xlfn.IFS(AB10>30,"ยังไม่ถึงเกณฑ์",AB10>0,"ใกล้ถึงเกณฑ์",AB10=0,"ถึงเกณฑ์",AB10<0,"ถึงเกณฑ์นานแล้ว") -> ยังไม่ถึงเกณฑ์
D11: 22/1/2018 | E11: นักทรัพยากรบุคคล | F11: K2 | G11: 20/1/2023 | H11: =DATEDIF(G11,$C$1,"Y") -> 0 | I11: =DATEDIF(G11,$C$1,"YM") -> 7 | J11: =DATEDIF(G11,$C$1,"MD") -> 12 | K11: นักทรัพยากรบุคคล | L11: K1 | M11: 22/1/2018 | N11: =DATEDIF(M11,G11,"Y") -> 4 | O11: =DATEDIF(M11,G11,"YM") -> 11 | P11: =DATEDIF(M11,G11,"MD") -> 29 | Q11: ป.โท | R11: นักทรัพยากรบุคคล | S11: K3 | T11: 1 | U11: =_xlfn.IFS(AND(T11=1,K11=R11,E11=R11),$C$1-M11,AND(T11=2,K11=R11,E11<>R11),G11-M11,AND(T11=2,K11<>R11,E11=R11),$C$1-G11,AND(K11<>R11,E11<>R11),0,T11>2,SUMIFS('นับวันใน-ตน.'!H:H,'นับวันใน-ตน.'!A:A,B11,'นับวันใน-ตน.'!B:B,R11),TRUE,0) -> 2048 | V11: =SUMIF(นับเกื้อกูล!A:A,B11,นับเกื้อกูล!I:I) -> 0 | W11: =U11+V11 -> 2048 | X11: =IF(W11>0,$C$1-W11,"Check Data") -> 43122 | Y11: =EDATE(G11,12*4) -> 46407 | Z11: =IFERROR(_xlfn.IFS(Q11="ป.ตรี",EDATE(X11,12*10),Q11="ป.ตรี 5 ปี",EDATE(X11,12*9),Q11="ป.ตรี 6 ปี",EDATE(X11,12*8),Q11="ป.โท",EDATE(X11,12*8),Q11="ป.เอก",EDATE(X11,12*6),TRUE,"Check Data"),"Check Data") -> 46044 | AA11: =IF(Y11>Z11,Y11,Z11) -> 46407 | AB11: =_xlfn.IFS(AND(TODAY()>Y11,Y11>Z11),Y11-TODAY(),AND(TODAY()>Z11,Z11>Y11),Z11-TODAY(),AND(TODAY()<Y11,Y11>Z11),DATEDIF(TODAY(),Y11,"d"),AND(TODAY()<Z11,Z11>Y11),DATEDIF(TODAY(),Z11,"d"),Y11=Z11,DATEDIF(TODAY(),Y11,"d")) -> 305 | AC11: =_xlfn.IFS(AB11>30,"ยังไม่ถึงเกณฑ์",AB11>0,"ใกล้ถึงเกณฑ์",AB11=0,"ถึงเกณฑ์",AB11<0,"ถึงเกณฑ์นานแล้ว") -> ยังไม่ถึงเกณฑ์
D12: 18/2/2022 | E12: นักทรัพยากรบุคคล | F12: K2 | G12: 19/1/2018 | H12: =DATEDIF(G12,$C$1,"Y") -> 5 | I12: =DATEDIF(G12,$C$1,"YM") -> 7 | J12: =DATEDIF(G12,$C$1,"MD") -> 13 | K12: นักทรัพยากรบุคคล | L12: K1 | M12: 18/2/2022 | N12: =DATEDIF(M12,G12,"Y") -> #NUM! | O12: =DATEDIF(M12,G12,"YM") -> #NUM! | P12: =DATEDIF(M12,G12,"MD") -> #NUM! | Q12: ป.โท | R12: นักทรัพยากรบุคคล | S12: K3 | T12: 1 | U12: =_xlfn.IFS(AND(T12=1,K12=R12,E12=R12),$C$1-M12,AND(T12=2,K12=R12,E12<>R12),G12-M12,AND(T12=2,K12<>R12,E12=R12),$C$1-G12,AND(K12<>R12,E12<>R12),0,T12>2,SUMIFS('นับวันใน-ตน.'!H:H,'นับวันใน-ตน.'!A:A,B12,'นับวันใน-ตน.'!B:B,R12),TRUE,0) -> 560 | V12: =SUMIF(นับเกื้อกูล!A:A,B12,นับเกื้อกูล!I:I) -> 0 | W12: =U12+V12 -> 560 | X12: =IF(W12>0,$C$1-W12,"Check Data") -> 44610 | Y12: =EDATE(G12,12*4) -> 44580 | Z12: =IFERROR(_xlfn.IFS(Q12="ป.ตรี",EDATE(X12,12*10),Q12="ป.ตรี 5 ปี",EDATE(X12,12*9),Q12="ป.ตรี 6 ปี",EDATE(X12,12*8),Q12="ป.โท",EDATE(X12,12*8),Q12="ป.เอก",EDATE(X12,12*6),TRUE,"Check Data"),"Check Data") -> 47532 | AA12: =IF(Y12>Z12,Y12,Z12) -> 47532 | AB12: =_xlfn.IFS(AND(TODAY()>Y12,Y12>Z12),Y12-TODAY(),AND(TODAY()>Z12,Z12>Y12),Z12-TODAY(),AND(TODAY()<Y12,Y12>Z12),DATEDIF(TODAY(),Y12,"d"),AND(TODAY()<Z12,Z12>Y12),DATEDIF(TODAY(),Z12,"d"),Y12=Z12,DATEDIF(TODAY(),Y12,"d")) -> 1430 | AC12: =_xlfn.IFS(AB12>30,"ยังไม่ถึงเกณฑ์",AB12>0,"ใกล้ถึงเกณฑ์",AB12=0,"ถึงเกณฑ์",AB12<0,"ถึงเกณฑ์นานแล้ว") -> ยังไม่ถึงเกณฑ์
D13: 28/9/1992 | E13: นักทรัพยากรบุคคล | F13: K2 | G13: 25/3/2015 | H13: =DATEDIF(G13,$C$1,"Y") -> 8 | I13: =DATEDIF(G13,$C$1,"YM") -> 5 | J13: =DATEDIF(G13,$C$1,"MD") -> 7 | K13: นักจัดการงานทั่วไป | L13: K1 | M13: 26/3/2013 | N13: =DATEDIF(M13,G13,"Y") -> 1 | O13: =DATEDIF(M13,G13,"YM") -> 11 | P13: =DATEDIF(M13,G13,"MD") -> 27 | Q13: ป.โท | R13: นักทรัพยากรบุคคล | S13: K3 | T13: 2 | U13: =_xlfn.IFS(AND(T13=1,K13=R13,E13=R13),$C$1-M13,AND(T13=2,K13=R13,E13<>R13),G13-M13,AND(T13=2,K13<>R13,E13=R13),$C$1-G13,AND(K13<>R13,E13<>R13),0,T13>2,SUMIFS('นับวันใน-ตน.'!H:H,'นับวันใน-ตน.'!A:A,B13,'นับวันใน-ตน.'!B:B,R13),TRUE,0) -> 3082 | V13: =SUMIF(นับเกื้อกูล!A:A,B13,นับเกื้อกูล!I:I) -> 0 | W13: =U13+V13 -> 3082 | X13: =IF(W13>0,$C$1-W13,"Check Data") -> 42088 | Y13: =EDATE(G13,12*4) -> 43549 | Z13: =IFERROR(_xlfn.IFS(Q13="ป.ตรี",EDATE(X13,12*10),Q13="ป.ตรี 5 ปี",EDATE(X13,12*9),Q13="ป.ตรี 6 ปี",EDATE(X13,12*8),Q13="ป.โท",EDATE(X13,12*8),Q13="ป.เอก",EDATE(X13,12*6),TRUE,"Check Data"),"Check Data") -> 45010 | AA13: =IF(Y13>Z13,Y13,Z13) -> 45010 | AB13: =_xlfn.IFS(AND(TODAY()>Y13,Y13>Z13),Y13-TODAY(),AND(TODAY()>Z13,Z13>Y13),Z13-TODAY(),AND(TODAY()<Y13,Y13>Z13),DATEDIF(TODAY(),Y13,"d"),AND(TODAY()<Z13,Z13>Y13),DATEDIF(TODAY(),Z13,"d"),Y13=Z13,DATEDIF(TODAY(),Y13,"d")) -> -1092 | AC13: =_xlfn.IFS(AB13>30,"ยังไม่ถึงเกณฑ์",AB13>0,"ใกล้ถึงเกณฑ์",AB13=0,"ถึงเกณฑ์",AB13<0,"ถึงเกณฑ์นานแล้ว") -> ถึงเกณฑ์นานแล้ว
D14: 1/9/2011 | E14: นักทรัพยากรบุคคล | F14: K2 | G14: 17/6/2016 | H14: =DATEDIF(G14,$C$1,"Y") -> 7 | I14: =DATEDIF(G14,$C$1,"YM") -> 2 | J14: =DATEDIF(G14,$C$1,"MD") -> 15 | K14: นักทรัพยากรบุคคล | L14: K1 | M14: 1/9/2011 | N14: =DATEDIF(M14,G14,"Y") -> 4 | O14: =DATEDIF(M14,G14,"YM") -> 9 | P14: =DATEDIF(M14,G14,"MD") -> 16 | Q14: ป.โท | R14: นักทรัพยากรบุคคล | S14: K3 | T14: 1 | U14: =_xlfn.IFS(AND(T14=1,K14=R14,E14=R14),$C$1-M14,AND(T14=2,K14=R14,E14<>R14),G14-M14,AND(T14=2,K14<>R14,E14=R14),$C$1-G14,AND(K14<>R14,E14<>R14),0,T14>2,SUMIFS('นับวันใน-ตน.'!H:H,'นับวันใน-ตน.'!A:A,B14,'นับวันใน-ตน.'!B:B,R14),TRUE,0) -> 4383 | V14: =SUMIF(นับเกื้อกูล!A:A,B14,นับเกื้อกูล!I:I) -> 0 | W14: =U14+V14 -> 4383 | X14: =IF(W14>0,$C$1-W14,"Check Data") -> 40787 | Y14: =EDATE(G14,12*4) -> 43999 | Z14: =IFERROR(_xlfn.IFS(Q14="ป.ตรี",EDATE(X14,12*10),Q14="ป.ตรี 5 ปี",EDATE(X14,12*9),Q14="ป.ตรี 6 ปี",EDATE(X14,12*8),Q14="ป.โท",EDATE(X14,12*8),Q14="ป.เอก",EDATE(X14,12*6),TRUE,"Check Data"),"Check Data") -> 43709 | AA14: =IF(Y14>Z14,Y14,Z14) -> 43999 | AB14: =_xlfn.IFS(AND(TODAY()>Y14,Y14>Z14),Y14-TODAY(),AND(TODAY()>Z14,Z14>Y14),Z14-TODAY(),AND(TODAY()<Y14,Y14>Z14),DATEDIF(TODAY(),Y14,"d"),AND(TODAY()<Z14,Z14>Y14),DATEDIF(TODAY(),Z14,"d"),Y14=Z14,DATEDIF(TODAY(),Y14,"d")) -> -2103 | AC14: =_xlfn.IFS(AB14>30,"ยังไม่ถึงเกณฑ์",AB14>0,"ใกล้ถึงเกณฑ์",AB14=0,"ถึงเกณฑ์",AB14<0,"ถึงเกณฑ์นานแล้ว") -> ถึงเกณฑ์นานแล้ว
... D21: 22/10/2012 | E21: นักวิเคราะห์นโยบายและแผน | F21: K2 | G21: 11/10/2017 | H21: =DATEDIF(G21,$C$1,"Y") -> 5 | I21: =DATEDIF(G21,$C$1,"YM") -> 10 | J21: =DATEDIF(G21,$C$1,"MD") -> 21 | K21: นักวิชาการยุติธรรม | L21: K1 | M21: 22/10/2012 | N21: =DATEDIF(M21,G21,"Y") -> 4 | O21: =DATEDIF(M21,G21,"YM") -> 11 | P21: =DATEDIF(M21,G21,"MD") -> 19 | Q21: ป.โท | R21: นักวิเคราะห์นโยบายและแผน | S21: K3 | T21: 2 | U21: =_xlfn.IFS(AND(T21=1,K21=R21,E21=R21),$C$1-M21,AND(T21=2,K21=R21,E21<>R21),G21-M21,AND(T21=2,K21<>R21,E21=R21),$C$1-G21,AND(K21<>R21,E21<>R21),0,T21>2,SUMIFS('นับวันใน-ตน.'!H:H,'นับวันใน-ตน.'!A:A,B21,'นับวันใน-ตน.'!B:B,R21),TRUE,0) -> 2151 | V21: =SUMIF(นับเกื้อกูล!A:A,B21,นับเกื้อกูล!I:I) -> 0 | W21: =U21+V21 -> 2151 | X21: =IF(W21>0,$C$1-W21,"Check Data") -> 43019 | Y21: =EDATE(G21,12*4) -> 44480 | Z21: =IFERROR(_xlfn.IFS(Q21="ป.ตรี",EDATE(X21,12*10),Q21="ป.ตรี 5 ปี",EDATE(X21,12*9),Q21="ป.ตรี 6 ปี",EDATE(X21,12*8),Q21="ป.โท",EDATE(X21,12*8),Q21="ป.เอก",EDATE(X21,12*6),TRUE,"Check Data"),"Check Data") -> 45941 | AA21: =IF(Y21>Z21,Y21,Z21) -> 45941 | AB21: =_xlfn.IFS(AND(TODAY()>Y21,Y21>Z21),Y21-TODAY(),AND(TODAY()>Z21,Z21>Y21),Z21-TODAY(),AND(TODAY()<Y21,Y21>Z21),DATEDIF(TODAY(),Y21,"d"),AND(TODAY()<Z21,Z21>Y21),DATEDIF(TODAY(),Z21,"d"),Y21=Z21,DATEDIF(TODAY(),Y21,"d")) -> -161 | AC21: =_xlfn.IFS(AB21>30,"ยังไม่ถึงเกณฑ์",AB21>0,"ใกล้ถึงเกณฑ์",AB21=0,"ถึงเกณฑ์",AB21<0,"ถึงเกณฑ์นานแล้ว") -> ถึงเกณฑ์นานแล้ว

Sheet K4-K5-LAW
B1: วันปิดรับสมัคร | C1: 45828 | J1: แปลง พศ เป็น คศ => | K1: 232387 | N1: =IF(AND(LEFT(K1,2)="29",MID(K1,4,1)="2"),LEFT(K1,2)&"/"&MID(K1,4,1)&"/"&RIGHT(K1,4)-543,EDATE(K1,-543*12)) -> 34060
A2: ลำดับที่ | B2: เลข ปชช. | C2: ชื่อ - นามสกุล | D2: กรม | E2: วันบรรจุ พ.ศ. | F2: วันบรรจุ ค.ศ. | G2: ปี | H2: เดือน | I2: วัน | J2: ตำแหน่งปัจจุบัน | K2: ประเภทระดับปัจจุบัน | N2: เงินเดือน | O2: เครื่องราชฯ | P2: เกษียณ | Q2: วันเข้าสู่ระดับปัจจุบัน พ.ศ. | R2: วันเข้าสู่ระดับปัจจุบัน ค.ศ. | U2: ปี | V2: เดือน | W2: วัน | Y2: ประเภทระดับ ก่อนปัจจุบัน 1 | Z2: วันเข้าสู่ระดับ ก่อนปัจจุบัน 1 พ.ศ. | AA2: วันเข้าสู่ระดับ ก่อนปัจจุบัน 1 ค.ศ. | AB2: ปี | AC2: เดือน | AD2: วัน | AE2: ประเภทระดับ ก่อนปัจจุบัน 2 | AF2: วันเข้าสู่ระดับ ก่อนปัจจุบัน 2 พ.ศ. | AG2: วันเข้าสู่ระดับ ก่อนปัจจุบัน 2 ค.ศ. | AH2: ปี | AI2: เดือน | AJ2: วัน | AK2: ระดับการศึกษา | AL2: วุฒิการศึกษา | AO2: ระดับที่จะเลื่อน | AP2: วันที่มีคุณสมบัติ ทรงคุณวุฒิ ค.ศ. | AQ2: วันที่มีคุณสมบัติ ทรงคุณวุฒิ พ.ศ. | AR2: จำนวนวันที่เหลือ | AS2: สถานะ | AT2: index_อส ชช รวม_level | AU2: from Q3 | AV2: check | AW2: last_col
A3: 1 | D3: สำนักงานกิจการยุติธรรม | E3: 12/05/2527 | F3: =IF(E3="","",TEXT(EDATE(E3,-543*12),"dd/mm/yyyy")) -> 12/05/1984 | G3: =IF(F3="",0,DATEDIF(F3,$C$1,"Y")) -> 41 | H3: =IF(F3="",0,DATEDIF(F3,$C$1,"YM")) -> 1 | I3: =IF(F3="",0,DATEDIF(F3,$C$1,"MD")) -> 8 | J3: รองผู้อำนวยการสำนักงานกิจการยุติธรรม | K3: S1 | L3: =IF(B3="","",IF(K3="S1",K3,INDEX(#REF!,#REF!))) | M3: =K3=L3 -> FALSE | P3: 2569 | Q3: 20/12/2562 | R3: =TEXT(EDATE(Q3,-543*12),"dd/mm/yyyy") -> 20/12/2019 | S3: =IF(B3="","",IF(K3="S1",K3,INDEX(#REF!,#REF!))) | T3: =Q3=S3 -> FALSE | U3: =IF(R3="",0,DATEDIF(R3,$C$1,"Y")) -> 5 | V3: =IF(R3="",0,DATEDIF(R3,$C$1,"YM")) -> 6 | W3: =IF(R3="",0,DATEDIF(R3,$C$1,"MD")) -> 0 | AA3: =IF(Z3="","",TEXT(EDATE(Z3,-543*12),"dd/mm/yyyy")) | AB3: =IF(AA3="",0,DATEDIF(AA3,R3,"Y")) -> 0 | AC3: =IF(AA3="",0,DATEDIF(AA3,R3,"YM")) -> 0 | AD3: =IF(AA3="",0,DATEDIF(AA3,R3,"MD")) -> 0 | AG3: =IF(AF3="","",TEXT(EDATE(AF3,-543*12),"dd/mm/yyyy")) | AH3: =IF(AG3="",0,DATEDIF(AG3,AA3,"Y")) -> 0 | AI3: =IF(AG3="",0,DATEDIF(AG3,AA3,"YM")) -> 0 | AJ3: =IF(AG3="",0,DATEDIF(AG3,AA3,"MD")) -> 0 | AL3: รัฐประศาสนศาสตรบัณฑิต | AM3: =IF(B3="","",IF(K3="S1",K3,INDEX(#REF!,#REF!))) | AN3: =AL3=AM3 -> FALSE | AO3: =IF(AL3="นิติศาสตร์","K5-LAW","K5-POLICY") -> K5-POLICY | AP3: =_xlfn.IFS(B3="","",AND(AO3="K5-LAW",AL3="นิติศาสตร์",K3="S2",Y3="",AE3=""),R3,AND(AO3="K5-LAW",AL3="นิติศาสตร์",K3="S1",Y3="",AE3=""),EDATE(R3,12),AND(AO3="K5-LAW",AL3="นิติศาสตร์",OR(K3="M2",K3="K4"),Y3="",AE3=""),EDATE(R3,12*2),AND(AO3="K5-LAW",AL3="นิติศาสตร์",OR(AE3="M2",AE3="K4"),AH3>=2,OR(AG3<AA3,AG3<R3)),EDATE(AG3,12*2),AND(AO3="K5-LAW",AL3="นิติศาสตร์",AE3="S1",AH3>=1,OR(AG3<AA3,AG3<R3)),EDATE(AG3,12),AND(AO3="K5-LAW",AL3="นิติศาสตร์",OR(Y3="M2",Y3="K4"),AB3>=2,AA3<R3),EDATE(AA3,12*2),AND(AO3="K5-LAW",AL3="นิติศาสตร์",Y3="S1",AB3>=1,AA3<R3),EDATE(AA3,12),AND(AO3="K5-LAW",AL3="นิติศาสตร์",OR(Y3="S2",Y3="K5")),AA3,AND(AO3="K5-LAW",AL3="นิติศาสตร์",OR(K3="M2",K3="K4"),U3>=2),EDATE(R3,12*2),AND(AO3="K5-LAW",AL3="นิติศาสตร์",K3="S1",U3>=1),EDATE(R3,12),AND(AO3="K5-LAW",AL3="นิติศาสตร์",OR(K3="S2",K3="K5")),R3,AND(AO3="K5-POLICY",AL3<>"นิติศาสตร์",K3="S2",Y3="",AE3=""),R3,AND(AO3="K5-POLICY",AL3<>"นิติศาสตร์",K3="S1",Y3="",AE3=""),EDATE(R3,12),AND(AO3="K5-POLICY",AL3<>"นิติศาสตร์",OR(K3="M2",K3="K4"),Y3="",AE3=""),EDATE(R3,12*2),AND(AO3="K5-POLICY",AL3<>"นิติศาสตร์",OR(AE3="M2",AE3="K4"),AH3>=2,OR(AG3<AA3,AG3<R3)),EDATE(AG3,12*2),AND(AO3="K5-POLICY",AL3<>"นิติศาสตร์",AE3="S1",AH3>=1,OR(AG3<AA3,AG3<R3)),EDATE(AG3,12),AND(AO3="K5-POLICY",AL3<>"นิติศาสตร์",OR(Y3="M2",Y3="K4"),AB3>=2,AA3<R3),EDATE(AA3,12*2),AND(AO3="K5-POLICY",AL3<>"นิติศาสตร์",Y3="S1",AB3>=1,AA3<R3),EDATE(AA3,12),AND(AO3="K5-POLICY",AL3<>"นิติศาสตร์",OR(Y3="S2",Y3="K5")),AA3,AND(AO3="K5-POLICY",AL3<>"นิติศาสตร์",OR(K3="M2",K3="K4"),U3>=2),EDATE(R3,12*2),AND(AO3="K5-POLICY",AL3<>"นิติศาสตร์",K3="S1",U3>=1),EDATE(R3,12),AND(AO3="K5-POLICY",AL3<>"นิติศาสตร์",OR(K3="S2",K3="K5")),R3,TRUE,"Check Data") | AQ3: =IFERROR(TEXT(EDATE(AP3,543*12),"dd/mm/yyyy"),"Check Data") -> Check Data | AR3: =IFERROR(IF($C$1>AP3,AP3-$C$1,DATEDIF($C$1,AP3,"d")),"Check Data") -> Check Data | AS3: =_xlfn.IFS(AR3="Check Data","Check Data",AR3>30,"ยังไม่ถึงเกณฑ์",AR3>0,"ใกล้ถึงเกณฑ์",AR3=0,"ถึงเกณฑ์",AR3<0,"ถึงเกณฑ์นานแล้ว") -> Check Data | AT3: =IF(B3="","",IF(K3="S1","S1",INDEX(#REF!,#REF!))) | AU3: =K3 -> S1 | AV3: =K3=AT3 -> FALSE
A4: 2 | D4: กรมคุมประพฤติ | E4: 06/03/2540 | F4: =IF(E4="","",TEXT(EDATE(E4,-543*12),"dd/mm/yyyy")) -> 06/03/1997 | G4: =IF(F4="",0,DATEDIF(F4,$C$1,"Y")) -> 28 | H4: =IF(F4="",0,DATEDIF(F4,$C$1,"YM")) -> 3 | I4: =IF(F4="",0,DATEDIF(F4,$C$1,"MD")) -> 14 | J4: รองอธิบดีกรมคุมประพฤติ | K4: S1 | L4: =IF(B4="","",IF(K4="S1",K4,INDEX(#REF!,#REF!))) | M4: =K4=L4 -> FALSE | P4: 2574 | Q4: 24/02/2563 | R4: =TEXT(EDATE(Q4,-543*12),"dd/mm/yyyy") -> 24/02/2020 | S4: =IF(B4="","",IF(K4="S1",K4,INDEX(#REF!,#REF!))) | T4: =Q4=S4 -> FALSE | U4: =IF(R4="",0,DATEDIF(R4,$C$1,"Y")) -> 5 | V4: =IF(R4="",0,DATEDIF(R4,$C$1,"YM")) -> 3 | W4: =IF(R4="",0,DATEDIF(R4,$C$1,"MD")) -> 27 | AA4: =IF(Z4="","",TEXT(EDATE(Z4,-543*12),"dd/mm/yyyy")) | AB4: =IF(AA4="",0,DATEDIF(AA4,R4,"Y")) -> 0 | AC4: =IF(AA4="",0,DATEDIF(AA4,R4,"YM")) -> 0 | AD4: =IF(AA4="",0,DATEDIF(AA4,R4,"MD")) -> 0 | AG4: =IF(AF4="","",TEXT(EDATE(AF4,-543*12),"dd/mm/yyyy")) | AH4: =IF(AG4="",0,DATEDIF(AG4,AA4,"Y")) -> 0 | AI4: =IF(AG4="",0,DATEDIF(AG4,AA4,"YM")) -> 0 | AJ4: =IF(AG4="",0,DATEDIF(AG4,AA4,"MD")) -> 0 | AL4: รัฐศาสตรบัณฑิต / ... | AM4: =IF(B4="","",IF(K4="S1",K4,INDEX(#REF!,#REF!))) | AN4: =AL4=AM4 -> FALSE | AO4: =IF(AL4="นิติศาสตร์","K5-LAW","K5-POLICY") -> K5-POLICY | AP4: =_xlfn.IFS(B4="","",AND(AO4="K5-LAW",AL4="นิติศาสตร์",K4="S2",Y4="",AE4=""),R4,AND(AO4="K5-LAW",AL4="นิติศาสตร์",K4="S1",Y4="",AE4=""),EDATE(R4,12),AND(AO4="K5-LAW",AL4="นิติศาสตร์",OR(K4="M2",K4="K4"),Y4="",AE4=""),EDATE(R4,12*2),AND(AO4="K5-LAW",AL4="นิติศาสตร์",OR(AE4="M2",AE4="K4"),AH4>=2,OR(AG4<AA4,AG4<R4)),EDATE(AG4,12*2),AND(AO4="K5-LAW",AL4="นิติศาสตร์",AE4="S1",AH4>=1,OR(AG4<AA4,AG4<R4)),EDATE(AG4,12),AND(AO4="K5-LAW",AL4="นิติศาสตร์",OR(Y4="M2",Y4="K4"),AB4>=2,AA4<R4),EDATE(AA4,12*2),AND(AO4="K5-LAW",AL4="นิติศาสตร์",Y4="S1",AB4>=1,AA4<R4),EDATE(AA4,12),AND(AO4="K5-LAW",AL4="นิติศาสตร์",OR(Y4="S2",Y4="K5")),AA4,AND(AO4="K5-LAW",AL4="นิติศาสตร์",OR(K4="M2",K4="K4"),U4>=2),EDATE(R4,12*2),AND(AO4="K5-LAW",AL4="นิติศาสตร์",K4="S1",U4>=1),EDATE(R4,12),AND(AO4="K5-LAW",AL4="นิติศาสตร์",OR(K4="S2",K4="K5")),R4,AND(AO4="K5-POLICY",AL4<>"นิติศาสตร์",K4="S2",Y4="",AE4=""),R4,AND(AO4="K5-POLICY",AL4<>"นิติศาสตร์",K4="S1",Y4="",AE4=""),EDATE(R4,12),AND(AO4="K5-POLICY",AL4<>"นิติศาสตร์",OR(K4="M2",K4="K4"),Y4="",AE4=""),EDATE(R4,12*2),AND(AO4="K5-POLICY",AL4<>"นิติศาสตร์",OR(AE4="M2",AE4="K4"),AH4>=2,OR(AG4<AA4,AG4<R4)),EDATE(AG4,12*2),AND(AO4="K5-POLICY",AL4<>"นิติศาสตร์",AE4="S1",AH4>=1,OR(AG4<AA4,AG4<R4)),EDATE(AG4,12),AND(AO4="K5-POLICY",AL4<>"นิติศาสตร์",OR(Y4="M2",Y4="K4"),AB4>=2,AA4<R4),EDATE(AA4,12*2),AND(AO4="K5-POLICY",AL4<>"นิติศาสตร์",Y4="S1",AB4>=1,AA4<R4),EDATE(AA4,12),AND(AO4="K5-POLICY",AL4<>"นิติศาสตร์",OR(Y4="S2",Y4="K5")),AA4,AND(AO4="K5-POLICY",AL4<>"นิติศาสตร์",OR(K4="M2",K4="K4"),U4>=2),EDATE(R4,12*2),AND(AO4="K5-POLICY",AL4<>"นิติศาสตร์",K4="S1",U4>=1),EDATE(R4,12),AND(AO4="K5-POLICY",AL4<>"นิติศาสตร์",OR(K4="S2",K4="K5")),R4,TRUE,"Check Data") | AQ4: =IFERROR(TEXT(EDATE(AP4,543*12),"dd/mm/yyyy"),"Check Data") -> Check Data | AR4: =IFERROR(IF($C$1>AP4,AP4-$C$1,DATEDIF($C$1,AP4,"d")),"Check Data") -> Check Data | AS4: =_xlfn.IFS(AR4="Check Data","Check Data",AR4>30,"ยังไม่ถึงเกณฑ์",AR4>0,"ใกล้ถึงเกณฑ์",AR4=0,"ถึงเกณฑ์",AR4<0,"ถึงเกณฑ์นานแล้ว") -> Check Data | AT4: =IF(B4="","",IF(K4="S1","S1",INDEX(#REF!,#REF!))) | AU4: =K4 -> S1 | AV4: =K4=AT4 -> FALSE
A5: 3 | D5: สถาบันนิติวิทยาศาสตร์ | E5: 01/04/2537 | F5: =IF(E5="","",TEXT(EDATE(E5,-543*12),"dd/mm/yyyy")) -> 01/04/1994 | G5: =IF(F5="",0,DATEDIF(F5,$C$1,"Y")) -> 31 | H5: =IF(F5="",0,DATEDIF(F5,$C$1,"YM")) -> 2 | I5: =IF(F5="",0,DATEDIF(F5,$C$1,"MD")) -> 19 | J5: รองผู้อำนวยการสถาบันนิติวิทยาศาสตร์ | K5: S1 | L5: =IF(B5="","",IF(K5="S1",K5,INDEX(#REF!,#REF!))) | M5: =K5=L5 -> FALSE | O5: ม.ว.ม. | P5: 2575 | Q5: 22/09/2563 | R5: =TEXT(EDATE(Q5,-543*12),"dd/mm/yyyy") -> 22/09/2020 | S5: =IF(B5="","",IF(K5="S1",K5,INDEX(#REF!,#REF!))) | T5: =Q5=S5 -> FALSE | U5: =IF(R5="",0,DATEDIF(R5,$C$1,"Y")) -> 4 | V5: =IF(R5="",0,DATEDIF(R5,$C$1,"YM")) -> 8 | W5: =IF(R5="",0,DATEDIF(R5,$C$1,"MD")) -> 29 | AA5: =IF(Z5="","",TEXT(EDATE(Z5,-543*12),"dd/mm/yyyy")) | AB5: =IF(AA5="",0,DATEDIF(AA5,R5,"Y")) -> 0 | AC5: =IF(AA5="",0,DATEDIF(AA5,R5,"YM")) -> 0 | AD5: =IF(AA5="",0,DATEDIF(AA5,R5,"MD")) -> 0 | AG5: =IF(AF5="","",TEXT(EDATE(AF5,-543*12),"dd/mm/yyyy")) | AH5: =IF(AG5="",0,DATEDIF(AG5,AA5,"Y")) -> 0 | AI5: =IF(AG5="",0,DATEDIF(AG5,AA5,"YM")) -> 0 | AJ5: =IF(AG5="",0,DATEDIF(AG5,AA5,"MD")) -> 0 | AL5: แพทยศาสตรบัณฑิต | AM5: =IF(B5="","",IF(K5="S1",K5,INDEX(#REF!,#REF!))) | AN5: =AL5=AM5 -> FALSE | AO5: =IF(AL5="นิติศาสตร์","K5-LAW","K5-POLICY") -> K5-POLICY | AP5: =_xlfn.IFS(B5="","",AND(AO5="K5-LAW",AL5="นิติศาสตร์",K5="S2",Y5="",AE5=""),R5,AND(AO5="K5-LAW",AL5="นิติศาสตร์",K5="S1",Y5="",AE5=""),EDATE(R5,12),AND(AO5="K5-LAW",AL5="นิติศาสตร์",OR(K5="M2",K5="K4"),Y5="",AE5=""),EDATE(R5,12*2),AND(AO5="K5-LAW",AL5="นิติศาสตร์",OR(AE5="M2",AE5="K4"),AH5>=2,OR(AG5<AA5,AG5<R5)),EDATE(AG5,12*2),AND(AO5="K5-LAW",AL5="นิติศาสตร์",AE5="S1",AH5>=1,OR(AG5<AA5,AG5<R5)),EDATE(AG5,12),AND(AO5="K5-LAW",AL5="นิติศาสตร์",OR(Y5="M2",Y5="K4"),AB5>=2,AA5<R5),EDATE(AA5,12*2),AND(AO5="K5-LAW",AL5="นิติศาสตร์",Y5="S1",AB5>=1,AA5<R5),EDATE(AA5,12),AND(AO5="K5-LAW",AL5="นิติศาสตร์",OR(Y5="S2",Y5="K5")),AA5,AND(AO5="K5-LAW",AL5="นิติศาสตร์",OR(K5="M2",K5="K4"),U5>=2),EDATE(R5,12*2),AND(AO5="K5-LAW",AL5="นิติศาสตร์",K5="S1",U5>=1),EDATE(R5,12),AND(AO5="K5-LAW",AL5="นิติศาสตร์",OR(K5="S2",K5="K5")),R5,AND(AO5="K5-POLICY",AL5<>"นิติศาสตร์",K5="S2",Y5="",AE5=""),R5,AND(AO5="K5-POLICY",AL5<>"นิติศาสตร์",K5="S1",Y5="",AE5=""),EDATE(R5,12),AND(AO5="K5-POLICY",AL5<>"นิติศาสตร์",OR(K5="M2",K5="K4"),Y5="",AE5=""),EDATE(R5,12*2),AND(AO5="K5-POLICY",AL5<>"นิติศาสตร์",OR(AE5="M2",AE5="K4"),AH5>=2,OR(AG5<AA5,AG5<R5)),EDATE(AG5,12*2),AND(AO5="K5-POLICY",AL5<>"นิติศาสตร์",AE5="S1",AH5>=1,OR(AG5<AA5,AG5<R5)),EDATE(AG5,12),AND(AO5="K5-POLICY",AL5<>"นิติศาสตร์",OR(Y5="M2",Y5="K4"),AB5>=2,AA5<R5),EDATE(AA5,12*2),AND(AO5="K5-POLICY",AL5<>"นิติศาสตร์",Y5="S1",AB5>=1,AA5<R5),EDATE(AA5,12),AND(AO5="K5-POLICY",AL5<>"นิติศาสตร์",OR(Y5="S2",Y5="K5")),AA5,AND(AO5="K5-POLICY",AL5<>"นิติศาสตร์",OR(K5="M2",K5="K4"),U5>=2),EDATE(R5,12*2),AND(AO5="K5-POLICY",AL5<>"นิติศาสตร์",K5="S1",U5>=1),EDATE(R5,12),AND(AO5="K5-POLICY",AL5<>"นิติศาสตร์",OR(K5="S2",K5="K5")),R5,TRUE,"Check Data") | AQ5: =IFERROR(TEXT(EDATE(AP5,543*12),"dd/mm/yyyy"),"Check Data") -> Check Data | AR5: =IFERROR(IF($C$1>AP5,AP5-$C$1,DATEDIF($C$1,AP5,"d")),"Check Data") -> Check Data | AS5: =_xlfn.IFS(AR5="Check Data","Check Data",AR5>30,"ยังไม่ถึงเกณฑ์",AR5>0,"ใกล้ถึงเกณฑ์",AR5=0,"ถึงเกณฑ์",AR5<0,"ถึงเกณฑ์นานแล้ว") -> Check Data | AT5: =IF(B5="","",IF(K5="S1","S1",INDEX(#REF!,#REF!))) | AU5: =K5 -> S1 | AV5: =K5=AT5 -> FALSE
A6: 4 | D6: กรมราชทัณฑ์ | E6: 08/05/2526 | F6: =IF(E6="","",TEXT(EDATE(E6,-543*12),"dd/mm/yyyy")) -> 08/05/1983 | G6: =IF(F6="",0,DATEDIF(F6,$C$1,"Y")) -> 42 | H6: =IF(F6="",0,DATEDIF(F6,$C$1,"YM")) -> 1 | I6: =IF(F6="",0,DATEDIF(F6,$C$1,"MD")) -> 12 | J6: รองอธิบดีกรมราชทัณฑ์ | K6: S1 | L6: =IF(B6="","",IF(K6="S1",K6,INDEX(#REF!,#REF!))) | M6: =K6=L6 -> FALSE | P6: 2568 | Q6: 09/03/2564 | R6: =TEXT(EDATE(Q6,-543*12),"dd/mm/yyyy") -> 09/03/2021 | S6: =IF(B6="","",IF(K6="S1",K6,INDEX(#REF!,#REF!))) | T6: =Q6=S6 -> FALSE | U6: =IF(R6="",0,DATEDIF(R6,$C$1,"Y")) -> 4 | V6: =IF(R6="",0,DATEDIF(R6,$C$1,"YM")) -> 3 | W6: =IF(R6="",0,DATEDIF(R6,$C$1,"MD")) -> 11 | AA6: =IF(Z6="","",TEXT(EDATE(Z6,-543*12),"dd/mm/yyyy")) | AB6: =IF(AA6="",0,DATEDIF(AA6,R6,"Y")) -> 0 | AC6: =IF(AA6="",0,DATEDIF(AA6,R6,"YM")) -> 0 | AD6: =IF(AA6="",0,DATEDIF(AA6,R6,"MD")) -> 0 | AG6: =IF(AF6="","",TEXT(EDATE(AF6,-543*12),"dd/mm/yyyy")) | AH6: =IF(AG6="",0,DATEDIF(AG6,AA6,"Y")) -> 0 | AI6: =IF(AG6="",0,DATEDIF(AG6,AA6,"YM")) -> 0 | AJ6: =IF(AG6="",0,DATEDIF(AG6,AA6,"MD")) -> 0 | AL6: รัฐประศาสนศาสตรบัณฑิต / ... | AM6: =IF(B6="","",IF(K6="S1",K6,INDEX(#REF!,#REF!))) | AN6: =AL6=AM6 -> FALSE | AO6: =IF(AL6="นิติศาสตร์","K5-LAW","K5-POLICY") -> K5-POLICY | AP6: =_xlfn.IFS(B6="","",AND(AO6="K5-LAW",AL6="นิติศาสตร์",K6="S2",Y6="",AE6=""),R6,AND(AO6="K5-LAW",AL6="นิติศาสตร์",K6="S1",Y6="",AE6=""),EDATE(R6,12),AND(AO6="K5-LAW",AL6="นิติศาสตร์",OR(K6="M2",K6="K4"),Y6="",AE6=""),EDATE(R6,12*2),AND(AO6="K5-LAW",AL6="นิติศาสตร์",OR(AE6="M2",AE6="K4"),AH6>=2,OR(AG6<AA6,AG6<R6)),EDATE(AG6,12*2),AND(AO6="K5-LAW",AL6="นิติศาสตร์",AE6="S1",AH6>=1,OR(AG6<AA6,AG6<R6)),EDATE(AG6,12),AND(AO6="K5-LAW",AL6="นิติศาสตร์",OR(Y6="M2",Y6="K4"),AB6>=2,AA6<R6),EDATE(AA6,12*2),AND(AO6="K5-LAW",AL6="นิติศาสตร์",Y6="S1",AB6>=1,AA6<R6),EDATE(AA6,12),AND(AO6="K5-LAW",AL6="นิติศาสตร์",OR(Y6="S2",Y6="K5")),AA6,AND(AO6="K5-LAW",AL6="นิติศาสตร์",OR(K6="M2",K6="K4"),U6>=2),EDATE(R6,12*2),AND(AO6="K5-LAW",AL6="นิติศาสตร์",K6="S1",U6>=1),EDATE(R6,12),AND(AO6="K5-LAW",AL6="นิติศาสตร์",OR(K6="S2",K6="K5")),R6,AND(AO6="K5-POLICY",AL6<>"นิติศาสตร์",K6="S2",Y6="",AE6=""),R6,AND(AO6="K5-POLICY",AL6<>"นิติศาสตร์",K6="S1",Y6="",AE6=""),EDATE(R6,12),AND(AO6="K5-POLICY",AL6<>"นิติศาสตร์",OR(K6="M2",K6="K4"),Y6="",AE6=""),EDATE(R6,12*2),AND(AO6="K5-POLICY",AL6<>"นิติศาสตร์",OR(AE6="M2",AE6="K4"),AH6>=2,OR(AG6<AA6,AG6<R6)),EDATE(AG6,12*2),AND(AO6="K5-POLICY",AL6<>"นิติศาสตร์",AE6="S1",AH6>=1,OR(AG6<AA6,AG6<R6)),EDATE(AG6,12),AND(AO6="K5-POLICY",AL6<>"นิติศาสตร์",OR(Y6="M2",Y6="K4"),AB6>=2,AA6<R6),EDATE(AA6,12*2),AND(AO6="K5-POLICY",AL6<>"นิติศาสตร์",Y6="S1",AB6>=1,AA6<R6),EDATE(AA6,12),AND(AO6="K5-POLICY",AL6<>"นิติศาสตร์",OR(Y6="S2",Y6="K5")),AA6,AND(AO6="K5-POLICY",AL6<>"นิติศาสตร์",OR(K6="M2",K6="K4"),U6>=2),EDATE(R6,12*2),AND(AO6="K5-POLICY",AL6<>"นิติศาสตร์",K6="S1",U6>=1),EDATE(R6,12),AND(AO6="K5-POLICY",AL6<>"นิติศาสตร์",OR(K6="S2",K6="K5")),R6,TRUE,"Check Data") | AQ6: =IFERROR(TEXT(EDATE(AP6,543*12),"dd/mm/yyyy"),"Check Data") -> Check Data | AR6: =IFERROR(IF($C$1>AP6,AP6-$C$1,DATEDIF($C$1,AP6,"d")),"Check Data") -> Check Data | AS6: =_xlfn.IFS(AR6="Check Data","Check Data",AR6>30,"ยังไม่ถึงเกณฑ์",AR6>0,"ใกล้ถึงเกณฑ์",AR6=0,"ถึงเกณฑ์",AR6<0,"ถึงเกณฑ์นานแล้ว") -> Check Data | AT6: =IF(B6="","",IF(K6="S1","S1",INDEX(#REF!,#REF!))) | AU6: =K6 -> S1 | AV6: =K6=AT6 -> FALSE
A7: 5 | D7: กรมพินิจและคุ้มครองเด็กและเยาวชน | E7: 10/11/2538 | F7: =IF(E7="","",TEXT(EDATE(E7,-543*12),"dd/mm/yyyy")) -> 10/11/1995 | G7: =IF(F7="",0,DATEDIF(F7,$C$1,"Y")) -> 29 | H7: =IF(F7="",0,DATEDIF(F7,$C$1,"YM")) -> 7 | I7: =IF(F7="",0,DATEDIF(F7,$C$1,"MD")) -> 10 | J7: รองอธิบดีกรมพินิจและคุ้มครองเด็กและเยาวชน | K7: S1 | L7: =IF(B7="","",IF(K7="S1",K7,INDEX(#REF!,#REF!))) | M7: =K7=L7 -> FALSE | P7: 2572 | Q7: 17/11/2564 | R7: =TEXT(EDATE(Q7,-543*12),"dd/mm/yyyy") -> 17/11/2021 | S7: =IF(B7="","",IF(K7="S1",K7,INDEX(#REF!,#REF!))) | T7: =Q7=S7 -> FALSE | U7: =IF(R7="",0,DATEDIF(R7,$C$1,"Y")) -> 3 | V7: =IF(R7="",0,DATEDIF(R7,$C$1,"YM")) -> 7 | W7: =IF(R7="",0,DATEDIF(R7,$C$1,"MD")) -> 3 | AA7: =IF(Z7="","",TEXT(EDATE(Z7,-543*12),"dd/mm/yyyy")) | AB7: =IF(AA7="",0,DATEDIF(AA7,R7,"Y")) -> 0 | AC7: =IF(AA7="",0,DATEDIF(AA7,R7,"YM")) -> 0 | AD7: =IF(AA7="",0,DATEDIF(AA7,R7,"MD")) -> 0 | AG7: =IF(AF7="","",TEXT(EDATE(AF7,-543*12),"dd/mm/yyyy")) | AH7: =IF(AG7="",0,DATEDIF(AG7,AA7,"Y")) -> 0 | AI7: =IF(AG7="",0,DATEDIF(AG7,AA7,"YM")) -> 0 | AJ7: =IF(AG7="",0,DATEDIF(AG7,AA7,"MD")) -> 0 | AL7: นิติศาสตร์ | AM7: =IF(B7="","",IF(K7="S1",K7,INDEX(#REF!,#REF!))) | AN7: =AL7=AM7 -> FALSE | AO7: =IF(AL7="นิติศาสตร์","K5-LAW","K5-POLICY") -> K5-LAW | AP7: =_xlfn.IFS(B7="","",AND(AO7="K5-LAW",AL7="นิติศาสตร์",K7="S2",Y7="",AE7=""),R7,AND(AO7="K5-LAW",AL7="นิติศาสตร์",K7="S1",Y7="",AE7=""),EDATE(R7,12),AND(AO7="K5-LAW",AL7="นิติศาสตร์",OR(K7="M2",K7="K4"),Y7="",AE7=""),EDATE(R7,12*2),AND(AO7="K5-LAW",AL7="นิติศาสตร์",OR(AE7="M2",AE7="K4"),AH7>=2,OR(AG7<AA7,AG7<R7)),EDATE(AG7,12*2),AND(AO7="K5-LAW",AL7="นิติศาสตร์",AE7="S1",AH7>=1,OR(AG7<AA7,AG7<R7)),EDATE(AG7,12),AND(AO7="K5-LAW",AL7="นิติศาสตร์",OR(Y7="M2",Y7="K4"),AB7>=2,AA7<R7),EDATE(AA7,12*2),AND(AO7="K5-LAW",AL7="นิติศาสตร์",Y7="S1",AB7>=1,AA7<R7),EDATE(AA7,12),AND(AO7="K5-LAW",AL7="นิติศาสตร์",OR(Y7="S2",Y7="K5")),AA7,AND(AO7="K5-LAW",AL7="นิติศาสตร์",OR(K7="M2",K7="K4"),U7>=2),EDATE(R7,12*2),AND(AO7="K5-LAW",AL7="นิติศาสตร์",K7="S1",U7>=1),EDATE(R7,12),AND(AO7="K5-LAW",AL7="นิติศาสตร์",OR(K7="S2",K7="K5")),R7,AND(AO7="K5-POLICY",AL7<>"นิติศาสตร์",K7="S2",Y7="",AE7=""),R7,AND(AO7="K5-POLICY",AL7<>"นิติศาสตร์",K7="S1",Y7="",AE7=""),EDATE(R7,12),AND(AO7="K5-POLICY",AL7<>"นิติศาสตร์",OR(K7="M2",K7="K4"),Y7="",AE7=""),EDATE(R7,12*2),AND(AO7="K5-POLICY",AL7<>"นิติศาสตร์",OR(AE7="M2",AE7="K4"),AH7>=2,OR(AG7<AA7,AG7<R7)),EDATE(AG7,12*2),AND(AO7="K5-POLICY",AL7<>"นิติศาสตร์",AE7="S1",AH7>=1,OR(AG7<AA7,AG7<R7)),EDATE(AG7,12),AND(AO7="K5-POLICY",AL7<>"นิติศาสตร์",OR(Y7="M2",Y7="K4"),AB7>=2,AA7<R7),EDATE(AA7,12*2),AND(AO7="K5-POLICY",AL7<>"นิติศาสตร์",Y7="S1",AB7>=1,AA7<R7),EDATE(AA7,12),AND(AO7="K5-POLICY",AL7<>"นิติศาสตร์",OR(Y7="S2",Y7="K5")),AA7,AND(AO7="K5-POLICY",AL7<>"นิติศาสตร์",OR(K7="M2",K7="K4"),U7>=2),EDATE(R7,12*2),AND(AO7="K5-POLICY",AL7<>"นิติศาสตร์",K7="S1",U7>=1),EDATE(R7,12),AND(AO7="K5-POLICY",AL7<>"นิติศาสตร์",OR(K7="S2",K7="K5")),R7,TRUE,"Check Data") | AQ7: =IFERROR(TEXT(EDATE(AP7,543*12),"dd/mm/yyyy"),"Check Data") -> Check Data | AR7: =IFERROR(IF($C$1>AP7,AP7-$C$1,DATEDIF($C$1,AP7,"d")),"Check Data") -> Check Data | AS7: =_xlfn.IFS(AR7="Check Data","Check Data",AR7>30,"ยังไม่ถึงเกณฑ์",AR7>0,"ใกล้ถึงเกณฑ์",AR7=0,"ถึงเกณฑ์",AR7<0,"ถึงเกณฑ์นานแล้ว") -> Check Data | AT7: =IF(B7="","",IF(K7="S1","S1",INDEX(#REF!,#REF!))) | AU7: =K7 -> S1 | AV7: =K7=AT7 -> FALSE
A8: 6 | D8: กรมพินิจและคุ้มครองเด็กและเยาวชน | E8: 23/12/2534 | F8: =IF(E8="","",TEXT(EDATE(E8,-543*12),"dd/mm/yyyy")) -> 23/12/1991 | G8: =IF(F8="",0,DATEDIF(F8,$C$1,"Y")) -> 33 | H8: =IF(F8="",0,DATEDIF(F8,$C$1,"YM")) -> 5 | I8: =IF(F8="",0,DATEDIF(F8,$C$1,"MD")) -> 28 | J8: รองอธิบดีกรมพินิจและคุ้มครองเด็ก และเยาวชน | K8: S1 | L8: =IF(B8="","",IF(K8="S1",K8,INDEX(#REF!,#REF!))) | M8: =K8=L8 -> FALSE | O8: ป.ช. | P8: 2572 | Q8: 17/11/2564 | R8: =TEXT(EDATE(Q8,-543*12),"dd/mm/yyyy") -> 17/11/2021 | S8: =IF(B8="","",IF(K8="S1",K8,INDEX(#REF!,#REF!))) | T8: =Q8=S8 -> FALSE | U8: =IF(R8="",0,DATEDIF(R8,$C$1,"Y")) -> 3 | V8: =IF(R8="",0,DATEDIF(R8,$C$1,"YM")) -> 7 | W8: =IF(R8="",0,DATEDIF(R8,$C$1,"MD")) -> 3 | AA8: =IF(Z8="","",TEXT(EDATE(Z8,-543*12),"dd/mm/yyyy")) | AB8: =IF(AA8="",0,DATEDIF(AA8,R8,"Y")) -> 0 | AC8: =IF(AA8="",0,DATEDIF(AA8,R8,"YM")) -> 0 | AD8: =IF(AA8="",0,DATEDIF(AA8,R8,"MD")) -> 0 | AG8: =IF(AF8="","",TEXT(EDATE(AF8,-543*12),"dd/mm/yyyy")) | AH8: =IF(AG8="",0,DATEDIF(AG8,AA8,"Y")) -> 0 | AI8: =IF(AG8="",0,DATEDIF(AG8,AA8,"YM")) -> 0 | AJ8: =IF(AG8="",0,DATEDIF(AG8,AA8,"MD")) -> 0 | AL8: ศิลปศาสตรบัณฑิต / ... | AM8: =IF(B8="","",IF(K8="S1",K8,INDEX(#REF!,#REF!))) | AN8: =AL8=AM8 -> FALSE | AO8: =IF(AL8="นิติศาสตร์","K5-LAW","K5-POLICY") -> K5-POLICY | AP8: =_xlfn.IFS(B8="","",AND(AO8="K5-LAW",AL8="นิติศาสตร์",K8="S2",Y8="",AE8=""),R8,AND(AO8="K5-LAW",AL8="นิติศาสตร์",K8="S1",Y8="",AE8=""),EDATE(R8,12),AND(AO8="K5-LAW",AL8="นิติศาสตร์",OR(K8="M2",K8="K4"),Y8="",AE8=""),EDATE(R8,12*2),AND(AO8="K5-LAW",AL8="นิติศาสตร์",OR(AE8="M2",AE8="K4"),AH8>=2,OR(AG8<AA8,AG8<R8)),EDATE(AG8,12*2),AND(AO8="K5-LAW",AL8="นิติศาสตร์",AE8="S1",AH8>=1,OR(AG8<AA8,AG8<R8)),EDATE(AG8,12),AND(AO8="K5-LAW",AL8="นิติศาสตร์",OR(Y8="M2",Y8="K4"),AB8>=2,AA8<R8),EDATE(AA8,12*2),AND(AO8="K5-LAW",AL8="นิติศาสตร์",Y8="S1",AB8>=1,AA8<R8),EDATE(AA8,12),AND(AO8="K5-LAW",AL8="นิติศาสตร์",OR(Y8="S2",Y8="K5")),AA8,AND(AO8="K5-LAW",AL8="นิติศาสตร์",OR(K8="M2",K8="K4"),U8>=2),EDATE(R8,12*2),AND(AO8="K5-LAW",AL8="นิติศาสตร์",K8="S1",U8>=1),EDATE(R8,12),AND(AO8="K5-LAW",AL8="นิติศาสตร์",OR(K8="S2",K8="K5")),R8,AND(AO8="K5-POLICY",AL8<>"นิติศาสตร์",K8="S2",Y8="",AE8=""),R8,AND(AO8="K5-POLICY",AL8<>"นิติศาสตร์",K8="S1",Y8="",AE8=""),EDATE(R8,12),AND(AO8="K5-POLICY",AL8<>"นิติศาสตร์",OR(K8="M2",K8="K4"),Y8="",AE8=""),EDATE(R8,12*2),AND(AO8="K5-POLICY",AL8<>"นิติศาสตร์",OR(AE8="M2",AE8="K4"),AH8>=2,OR(AG8<AA8,AG8<R8)),EDATE(AG8,12*2),AND(AO8="K5-POLICY",AL8<>"นิติศาสตร์",AE8="S1",AH8>=1,OR(AG8<AA8,AG8<R8)),EDATE(AG8,12),AND(AO8="K5-POLICY",AL8<>"นิติศาสตร์",OR(Y8="M2",Y8="K4"),AB8>=2,AA8<R8),EDATE(AA8,12*2),AND(AO8="K5-POLICY",AL8<>"นิติศาสตร์",Y8="S1",AB8>=1,AA8<R8),EDATE(AA8,12),AND(AO8="K5-POLICY",AL8<>"นิติศาสตร์",OR(Y8="S2",Y8="K5")),AA8,AND(AO8="K5-POLICY",AL8<>"นิติศาสตร์",OR(K8="M2",K8="K4"),U8>=2),EDATE(R8,12*2),AND(AO8="K5-POLICY",AL8<>"นิติศาสตร์",K8="S1",U8>=1),EDATE(R8,12),AND(AO8="K5-POLICY",AL8<>"นิติศาสตร์",OR(K8="S2",K8="K5")),R8,TRUE,"Check Data") | AQ8: =IFERROR(TEXT(EDATE(AP8,543*12),"dd/mm/yyyy"),"Check Data") -> Check Data | AR8: =IFERROR(IF($C$1>AP8,AP8-$C$1,DATEDIF($C$1,AP8,"d")),"Check Data") -> Check Data | AS8: =_xlfn.IFS(AR8="Check Data","Check Data",AR8>30,"ยังไม่ถึงเกณฑ์",AR8>0,"ใกล้ถึงเกณฑ์",AR8=0,"ถึงเกณฑ์",AR8<0,"ถึงเกณฑ์นานแล้ว") -> Check Data | AT8: =IF(B8="","",IF(K8="S1","S1",INDEX(#REF!,#REF!))) | AU8: =K8 -> S1 | AV8: =K8=AT8 -> FALSE
A9: 7 | D9: กรมราชทัณฑ์ | E9: 30/11/2536 | F9: =IF(E9="","",TEXT(EDATE(E9,-543*12),"dd/mm/yyyy")) -> 30/11/1993 | G9: =IF(F9="",0,DATEDIF(F9,$C$1,"Y")) -> 31 | H9: =IF(F9="",0,DATEDIF(F9,$C$1,"YM")) -> 6 | I9: =IF(F9="",0,DATEDIF(F9,$C$1,"MD")) -> 21 | J9: รองอธิบดีกรมราชทัณฑ์ | K9: S1 | L9: =IF(B9="","",IF(K9="S1",K9,INDEX(#REF!,#REF!))) | M9: =K9=L9 -> FALSE | O9: ป.ช. | P9: 2574 | Q9: 21/01/2565 | R9: =TEXT(EDATE(Q9,-543*12),"dd/mm/yyyy") -> 21/01/2022 | S9: =IF(B9="","",IF(K9="S1",K9,INDEX(#REF!,#REF!))) | T9: =Q9=S9 -> FALSE | U9: =IF(R9="",0,DATEDIF(R9,$C$1,"Y")) -> 3 | V9: =IF(R9="",0,DATEDIF(R9,$C$1,"YM")) -> 4 | W9: =IF(R9="",0,DATEDIF(R9,$C$1,"MD")) -> 30 | AA9: =IF(Z9="","",TEXT(EDATE(Z9,-543*12),"dd/mm/yyyy")) | AB9: =IF(AA9="",0,DATEDIF(AA9,R9,"Y")) -> 0 | AC9: =IF(AA9="",0,DATEDIF(AA9,R9,"YM")) -> 0 | AD9: =IF(AA9="",0,DATEDIF(AA9,R9,"MD")) -> 0 | AG9: =IF(AF9="","",TEXT(EDATE(AF9,-543*12),"dd/mm/yyyy")) | AH9: =IF(AG9="",0,DATEDIF(AG9,AA9,"Y")) -> 0 | AI9: =IF(AG9="",0,DATEDIF(AG9,AA9,"YM")) -> 0 | AJ9: =IF(AG9="",0,DATEDIF(AG9,AA9,"MD")) -> 0 | AL9: ศึกษาบัณฑิต / ... | AM9: =IF(B9="","",IF(K9="S1",K9,INDEX(#REF!,#REF!))) | AN9: =AL9=AM9 -> FALSE | AO9: =IF(AL9="นิติศาสตร์","K5-LAW","K5-POLICY") -> K5-POLICY | AP9: =_xlfn.IFS(B9="","",AND(AO9="K5-LAW",AL9="นิติศาสตร์",K9="S2",Y9="",AE9=""),R9,AND(AO9="K5-LAW",AL9="นิติศาสตร์",K9="S1",Y9="",AE9=""),EDATE(R9,12),AND(AO9="K5-LAW",AL9="นิติศาสตร์",OR(K9="M2",K9="K4"),Y9="",AE9=""),EDATE(R9,12*2),AND(AO9="K5-LAW",AL9="นิติศาสตร์",OR(AE9="M2",AE9="K4"),AH9>=2,OR(AG9<AA9,AG9<R9)),EDATE(AG9,12*2),AND(AO9="K5-LAW",AL9="นิติศาสตร์",AE9="S1",AH9>=1,OR(AG9<AA9,AG9<R9)),EDATE(AG9,12),AND(AO9="K5-LAW",AL9="นิติศาสตร์",OR(Y9="M2",Y9="K4"),AB9>=2,AA9<R9),EDATE(AA9,12*2),AND(AO9="K5-LAW",AL9="นิติศาสตร์",Y9="S1",AB9>=1,AA9<R9),EDATE(AA9,12),AND(AO9="K5-LAW",AL9="นิติศาสตร์",OR(Y9="S2",Y9="K5")),AA9,AND(AO9="K5-LAW",AL9="นิติศาสตร์",OR(K9="M2",K9="K4"),U9>=2),EDATE(R9,12*2),AND(AO9="K5-LAW",AL9="นิติศาสตร์",K9="S1",U9>=1),EDATE(R9,12),AND(AO9="K5-LAW",AL9="นิติศาสตร์",OR(K9="S2",K9="K5")),R9,AND(AO9="K5-POLICY",AL9<>"นิติศาสตร์",K9="S2",Y9="",AE9=""),R9,AND(AO9="K5-POLICY",AL9<>"นิติศาสตร์",K9="S1",Y9="",AE9=""),EDATE(R9,12),AND(AO9="K5-POLICY",AL9<>"นิติศาสตร์",OR(K9="M2",K9="K4"),Y9="",AE9=""),EDATE(R9,12*2),AND(AO9="K5-POLICY",AL9<>"นิติศาสตร์",OR(AE9="M2",AE9="K4"),AH9>=2,OR(AG9<AA9,AG9<R9)),EDATE(AG9,12*2),AND(AO9="K5-POLICY",AL9<>"นิติศาสตร์",AE9="S1",AH9>=1,OR(AG9<AA9,AG9<R9)),EDATE(AG9,12),AND(AO9="K5-POLICY",AL9<>"นิติศาสตร์",OR(Y9="M2",Y9="K4"),AB9>=2,AA9<R9),EDATE(AA9,12*2),AND(AO9="K5-POLICY",AL9<>"นิติศาสตร์",Y9="S1",AB9>=1,AA9<R9),EDATE(AA9,12),AND(AO9="K5-POLICY",AL9<>"นิติศาสตร์",OR(Y9="S2",Y9="K5")),AA9,AND(AO9="K5-POLICY",AL9<>"นิติศาสตร์",OR(K9="M2",K9="K4"),U9>=2),EDATE(R9,12*2),AND(AO9="K5-POLICY",AL9<>"นิติศาสตร์",K9="S1",U9>=1),EDATE(R9,12),AND(AO9="K5-POLICY",AL9<>"นิติศาสตร์",OR(K9="S2",K9="K5")),R9,TRUE,"Check Data") | AQ9: =IFERROR(TEXT(EDATE(AP9,543*12),"dd/mm/yyyy"),"Check Data") -> Check Data | AR9: =IFERROR(IF($C$1>AP9,AP9-$C$1,DATEDIF($C$1,AP9,"d")),"Check Data") -> Check Data | AS9: =_xlfn.IFS(AR9="Check Data","Check Data",AR9>30,"ยังไม่ถึงเกณฑ์",AR9>0,"ใกล้ถึงเกณฑ์",AR9=0,"ถึงเกณฑ์",AR9<0,"ถึงเกณฑ์นานแล้ว") -> Check Data | AT9: =IF(B9="","",IF(K9="S1","S1",INDEX(#REF!,#REF!))) | AU9: =K9 -> S1 | AV9: =K9=AT9 -> FALSE
